Workbook
Name TotalMonthlyExpenses: SUM(#REF!)
Name TotalMonthlyIncome: SUM(#REF!)

Sheet 대시보드
C2: (주) 넷폼알앤디 2026년 매출현황
C6: 목표매출 | E6: 계약매출 | G6: 확정매출 | I6: 달성률 | K6: 수금예정액 | M6: 관리미수금 | O6: 수금률
C7: 23000000000 | E7: =Q13 -> 612945600 | G7: =Q17 -> 50154600 | I7: =IF(C7>0, G7/C7, 0) -> 0.0021806348 | K7: =(SUM(컨설팅!P:P)+SUM(S_N솔루션!P:P)+SUM(특허기술자문료!P:P)) -> 650956900 | M7: =(SUMIF(컨설팅!S:S,"확인요망",컨설팅!H:H)+SUMIF(S_N솔루션!S:S,"확인요망",S_N솔루션!H:H)+SUMIF(특허기술자문료!S:S,"확인요망",특허기술자문료!I:I)) -> 0 | O7: =IF(G7>0, (SUM(컨설팅!O:O)+SUM(S_N솔루션!O:O)+SUM(특허기술자문료!O:O))/1.1/G7, 0) -> 0.36119518
C11: 1. 월별 계약 매출
C12: 계약일기준 | D12: 25년12월 | E12: 1월 | F12: 2월 | G12: 3월 | H12: 4월 | I12: 5월 | J12: 6월 | K12: 7월 | L12: 8월 | M12: 9월 | N12: 10월 | O12: 11월 | P12: 12월 | Q12: 합계
C13: 총액 | D13: =SUMIFS(컨설팅!H:H,컨설팅!J:J,">="&DATE(2025,12,1),컨설팅!J:J,"<="&EOMONTH(DATE(2025,12,1),0))+SUMIFS(S_N솔루션!H:H,S_N솔루션!J:J,">="&DATE(2025,12,1),S_N솔루션!J:J,"<="&EOMONTH(DATE(2025,12,1),0))+SUMIFS(특허기술자문료!I:I,특허기술자문료!J:J,">="&DATE(2025,12,1),특허기술자문료!J:J,"<="&EOMONTH(DATE(2025,12,1),0))+SUMPRODUCT((LEFT(자재판매!A2:A500,7)="2025-12")*(자재판매!P2:P500)) -> 580906600 | E13: =SUMIFS(컨설팅!H:H,컨설팅!J:J,">="&DATE(2026,1,1),컨설팅!J:J,"<="&EOMONTH(DATE(2026,1,1),0))+SUMIFS(S_N솔루션!H:H,S_N솔루션!J:J,">="&DATE(2026,1,1),S_N솔루션!J:J,"<="&EOMONTH(DATE(2026,1,1),0))+SUMIFS(특허기술자문료!I:I,특허기술자문료!J:J,">="&DATE(2026,1,1),특허기술자문료!J:J,"<="&EOMONTH(DATE(2026,1,1),0))+SUMPRODUCT((LEFT(자재판매!A2:A500,7)="2026-01")*(자재판매!P2:P500)) -> 32039000 | F13: =SUMIFS(컨설팅!H:H,컨설팅!J:J,">="&DATE(2026,2,1),컨설팅!J:J,"<="&EOMONTH(DATE(2026,2,1),0))+SUMIFS(S_N솔루션!H:H,S_N솔루션!J:J,">="&DATE(2026,2,1),S_N솔루션!J:J,"<="&EOMONTH(DATE(2026,2,1),0))+SUMIFS(특허기술자문료!I:I,특허기술자문료!J:J,">="&DATE(2026,2,1),특허기술자문료!J:J,"<="&EOMONTH(DATE(2026,2,1),0))+SUMPRODUCT((LEFT(자재판매!A2:A500,7)="2026-02")*(자재판매!P2:P500)) -> 0 | G13: =SUMIFS(컨설팅!H:H,컨설팅!J:J,">="&DATE(2026,3,1),컨설팅!J:J,"<="&EOMONTH(DATE(2026,3,1),0))+SUMIFS(S_N솔루션!H:H,S_N솔루션!J:J,">="&DATE(2026,3,1),S_N솔루션!J:J,"<="&EOMONTH(DATE(2026,3,1),0))+SUMIFS(특허기술자문료!I:I,특허기술자문료!J:J,">="&DATE(2026,3,1),특허기술자문료!J:J,"<="&EOMONTH(DATE(2026,3,1),0))+SUMPRODUCT((LEFT(자재판매!A2:A500,7)="2026-03")*(자재판매!P2:P500)) -> 0 | H13: =SUMIFS(컨설팅!H:H,컨설팅!J:J,">="&DATE(2026,4,1),컨설팅!J:J,"<="&EOMONTH(DATE(2026,4,1),0))+SUMIFS(S_N솔루션!H:H,S_N솔루션!J:J,">="&DATE(2026,4,1),S_N솔루션!J:J,"<="&EOMONTH(DATE(2026,4,1),0))+SUMIFS(특허기술자문료!I:I,특허기술자문료!J:J,">="&DATE(2026,4,1),특허기술자문료!J:J,"<="&EOMONTH(DATE(2026,4,1),0))+SUMPRODUCT((LEFT(자재판매!A2:A500,7)="2026-04")*(자재판매!P2:P500)) -> 0 | I13: =SUMIFS(컨설팅!H:H,컨설팅!J:J,">="&DATE(2026,5,1),컨설팅!J:J,"<="&EOMONTH(DATE(2026,5,1),0))+SUMIFS(S_N솔루션!H:H,S_N솔루션!J:J,">="&DATE(2026,5,1),S_N솔루션!J:J,"<="&EOMONTH(DATE(2026,5,1),0))+SUMIFS(특허기술자문료!I:I,특허기술자문료!J:J,">="&DATE(2026,5,1),특허기술자문료!J:J,"<="&EOMONTH(DATE(2026,5,1),0))+SUMPRODUCT((LEFT(자재판매!A2:A500,7)="2026-05")*(자재판매!P2:P500)) -> 0 | J13: =SUMIFS(컨설팅!H:H,컨설팅!J:J,">="&DATE(2026,6,1),컨설팅!J:J,"<="&EOMONTH(DATE(2026,6,1),0))+SUMIFS(S_N솔루션!H:H,S_N솔루션!J:J,">="&DATE(2026,6,1),S_N솔루션!J:J,"<="&EOMONTH(DATE(2026,6,1),0))+SUMIFS(특허기술자문료!I:I,특허기술자문료!J:J,">="&DATE(2026,6,1),특허기술자문료!J:J,"<="&EOMONTH(DATE(2026,6,1),0))+SUMPRODUCT((LEFT(자재판매!A2:A500,7)="2026-06")*(자재판매!P2:P500)) -> 0 | K13: =SUMIFS(컨설팅!H:H,컨설팅!J:J,">="&DATE(2026,7,1),컨설팅!J:J,"<="&EOMONTH(DATE(2026,7,1),0))+SUMIFS(S_N솔루션!H:H,S_N솔루션!J:J,">="&DATE(2026,7,1),S_N솔루션!J:J,"<="&EOMONTH(DATE(2026,7,1),0))+SUMIFS(특허기술자문료!I:I,특허기술자문료!J:J,">="&DATE(2026,7,1),특허기술자문료!J:J,"<="&EOMONTH(DATE(2026,7,1),0))+SUMPRODUCT((LEFT(자재판매!A2:A500,7)="2026-07")*(자재판매!P2:P500)) -> 0 | L13: =SUMIFS(컨설팅!H:H,컨설팅!J:J,">="&DATE(2026,8,1),컨설팅!J:J,"<="&EOMONTH(DATE(2026,8,1),0))+SUMIFS(S_N솔루션!H:H,S_N솔루션!J:J,">="&DATE(2026,8,1),S_N솔루션!J:J,"<="&EOMONTH(DATE(2026,8,1),0))+SUMIFS(특허기술자문료!I:I,특허기술자문료!J:J,">="&DATE(2026,8,1),특허기술자문료!J:J,"<="&EOMONTH(DATE(2026,8,1),0))+SUMPRODUCT((LEFT(자재판매!A2:A500,7)="2026-08")*(자재판매!P2:P500)) -> 0 | M13: =SUMIFS(컨설팅!H:H,컨설팅!J:J,">="&DATE(2026,9,1),컨설팅!J:J,"<="&EOMONTH(DATE(2026,9,1),0))+SUMIFS(S_N솔루션!H:H,S_N솔루션!J:J,">="&DATE(2026,9,1),S_N솔루션!J:J,"<="&EOMONTH(DATE(2026,9,1),0))+SUMIFS(특허기술자문료!I:I,특허기술자문료!J:J,">="&DATE(2026,9,1),특허기술자문료!J:J,"<="&EOMONTH(DATE(2026,9,1),0))+SUMPRODUCT((LEFT(자재판매!A2:A500,7)="2026-09")*(자재판매!P2:P500)) -> 0 | N13: =SUMIFS(컨설팅!H:H,컨설팅!J:J,">="&DATE(2026,10,1),컨설팅!J:J,"<="&EOMONTH(DATE(2026,10,1),0))+SUMIFS(S_N솔루션!H:H,S_N솔루션!J:J,">="&DATE(2026,10,1),S_N솔루션!J:J,"<="&EOMONTH(DATE(2026,10,1),0))+SUMIFS(특허기술자문료!I:I,특허기술자문료!J:J,">="&DATE(2026,10,1),특허기술자문료!J:J,"<="&EOMONTH(DATE(2026,10,1),0))+SUMPRODUCT((LEFT(자재판매!A2:A500,7)="2026-10")*(자재판매!P2:P500)) -> 0 | O13: =SUMIFS(컨설팅!H:H,컨설팅!J:J,">="&DATE(2026,11,1),컨설팅!J:J,"<="&EOMONTH(DATE(2026,11,1),0))+SUMIFS(S_N솔루션!H:H,S_N솔루션!J:J,">="&DATE(2026,11,1),S_N솔루션!J:J,"<="&EOMONTH(DATE(2026,11,1),0))+SUMIFS(특허기술자문료!I:I,특허기술자문료!J:J,">="&DATE(2026,11,1),특허기술자문료!J:J,"<="&EOMONTH(DATE(2026,11,1),0))+SUMPRODUCT((LEFT(자재판매!A2:A500,7)="2026-11")*(자재판매!P2:P500)) -> 0 | P13: =SUMIFS(컨설팅!H:H,컨설팅!J:J,">="&DATE(2026,12,1),컨설팅!J:J,"<="&EOMONTH(DATE(2026,12,1),0))+SUMIFS(S_N솔루션!H:H,S_N솔루션!J:J,">="&DATE(2026,12,1),S_N솔루션!J:J,"<="&EOMONTH(DATE(2026,12,1),0))+SUMIFS(특허기술자문료!I:I,특허기술자문료!J:J,">="&DATE(2026,12,1),특허기술자문료!J:J,"<="&EOMONTH(DATE(2026,12,1),0))+SUMPRODUCT((LEFT(자재판매!A2:A500,7)="2026-12")*(자재판매!P2:P500)) -> 0 | Q13: =SUM(D13:P13) -> 612945600
C15: 2. 월별 확정 매출
C16: 매출일기준 | D16: 25년12월 | E16: 1월 | F16: 2월 | G16: 3월 | H16: 4월 | I16: 5월 | J16: 6월 | K16: 7월 | L16: 8월 | M16: 9월 | N16: 10월 | O16: 11월 | P16: 12월 | Q16: 합계
C17: 총액 | D17: =SUMIFS(컨설팅!H:H,컨설팅!L:L,">="&DATE(2025,12,1),컨설팅!L:L,"<="&EOMONTH(DATE(2025,12,1),0))+SUMIFS(S_N솔루션!H:H,S_N솔루션!K:K,">="&DATE(2025,12,1),S_N솔루션!K:K,"<="&EOMONTH(DATE(2025,12,1),0))+SUMIFS(특허기술자문료!I:I,특허기술자문료!K:K,">="&DATE(2025,12,1),특허기술자문료!K:K,"<="&EOMONTH(DATE(2025,12,1),0))+SUMPRODUCT((LEFT(자재판매!A2:A500,7)="2025-12")*(자재판매!P2:P500)) -> 0 | E17: =SUMIFS(컨설팅!H:H,컨설팅!L:L,">="&DATE(2026,1,1),컨설팅!L:L,"<="&EOMONTH(DATE(2026,1,1),0))+SUMIFS(S_N솔루션!H:H,S_N솔루션!K:K,">="&DATE(2026,1,1),S_N솔루션!K:K,"<="&EOMONTH(DATE(2026,1,1),0))+SUMIFS(특허기술자문료!I:I,특허기술자문료!K:K,">="&DATE(2026,1,1),특허기술자문료!K:K,"<="&EOMONTH(DATE(2026,1,1),0))+SUMPRODUCT((LEFT(자재판매!A2:A500,7)="2026-01")*(자재판매!P2:P500)) -> 50154600 | F17: =SUMIFS(컨설팅!H:H,컨설팅!L:L,">="&DATE(2026,2,1),컨설팅!L:L,"<="&EOMONTH(DATE(2026,2,1),0))+SUMIFS(S_N솔루션!H:H,S_N솔루션!K:K,">="&DATE(2026,2,1),S_N솔루션!K:K,"<="&EOMONTH(DATE(2026,2,1),0))+SUMIFS(특허기술자문료!I:I,특허기술자문료!K:K,">="&DATE(2026,2,1),특허기술자문료!K:K,"<="&EOMONTH(DATE(2026,2,1),0))+SUMPRODUCT((LEFT(자재판매!A2:A500,7)="2026-02")*(자재판매!P2:P500)) -> 0 | G17: =SUMIFS(컨설팅!H:H,컨설팅!L:L,">="&DATE(2026,3,1),컨설팅!L:L,"<="&EOMONTH(DATE(2026,3,1),0))+SUMIFS(S_N솔루션!H:H,S_N솔루션!K:K,">="&DATE(2026,3,1),S_N솔루션!K:K,"<="&EOMONTH(DATE(2026,3,1),0))+SUMIFS(특허기술자문료!I:I,특허기술자문료!K:K,">="&DATE(2026,3,1),특허기술자문료!K:K,"<="&EOMONTH(DATE(2026,3,1),0))+SUMPRODUCT((LEFT(자재판매!A2:A500,7)="2026-03")*(자재판매!P2:P500)) -> 0 | H17: =SUMIFS(컨설팅!H:H,컨설팅!L:L,">="&DATE(2026,4,1),컨설팅!L:L,"<="&EOMONTH(DATE(2026,4,1),0))+SUMIFS(S_N솔루션!H:H,S_N솔루션!K:K,">="&DATE(2026,4,1),S_N솔루션!K:K,"<="&EOMONTH(DATE(2026,4,1),0))+SUMIFS(특허기술자문료!I:I,특허기술자문료!K:K,">="&DATE(2026,4,1),특허기술자문료!K:K,"<="&EOMONTH(DATE(2026,4,1),0))+SUMPRODUCT((LEFT(자재판매!A2:A500,7)="2026-04")*(자재판매!P2:P500)) -> 0 | I17: =SUMIFS(컨설팅!H:H,컨설팅!L:L,">="&DATE(2026,5,1),컨설팅!L:L,"<="&EOMONTH(DATE(2026,5,1),0))+SUMIFS(S_N솔루션!H:H,S_N솔루션!K:K,">="&DATE(2026,5,1),S_N솔루션!K:K,"<="&EOMONTH(DATE(2026,5,1),0))+SUMIFS(특허기술자문료!I:I,특허기술자문료!K:K,">="&DATE(2026,5,1),특허기술자문료!K:K,"<="&EOMONTH(DATE(2026,5,1),0))+SUMPRODUCT((LEFT(자재판매!A2:A500,7)="2026-05")*(자재판매!P2:P500)) -> 0 | J17: =SUMIFS(컨설팅!H:H,컨설팅!L:L,">="&DATE(2026,6,1),컨설팅!L:L,"<="&EOMONTH(DATE(2026,6,1),0))+SUMIFS(S_N솔루션!H:H,S_N솔루션!K:K,">="&DATE(2026,6,1),S_N솔루션!K:K,"<="&EOMONTH(DATE(2026,6,1),0))+SUMIFS(특허기술자문료!I:I,특허기술자문료!K:K,">="&DATE(2026,6,1),특허기술자문료!K:K,"<="&EOMONTH(DATE(2026,6,1),0))+SUMPRODUCT((LEFT(자재판매!A2:A500,7)="2026-06")*(자재판매!P2:P500)) -> 0 | K17: =SUMIFS(컨설팅!H:H,컨설팅!L:L,">="&DATE(2026,7,1),컨설팅!L:L,"<="&EOMONTH(DATE(2026,7,1),0))+SUMIFS(S_N솔루션!H:H,S_N솔루션!K:K,">="&DATE(2026,7,1),S_N솔루션!K:K,"<="&EOMONTH(DATE(2026,7,1),0))+SUMIFS(특허기술자문료!I:I,특허기술자문료!K:K,">="&DATE(2026,7,1),특허기술자문료!K:K,"<="&EOMONTH(DATE(2026,7,1),0))+SUMPRODUCT((LEFT(자재판매!A2:A500,7)="2026-07")*(자재판매!P2:P500)) -> 0 | L17: =SUMIFS(컨설팅!H:H,컨설팅!L:L,">="&DATE(2026,8,1),컨설팅!L:L,"<="&EOMONTH(DATE(2026,8,1),0))+SUMIFS(S_N솔루션!H:H,S_N솔루션!K:K,">="&DATE(2026,8,1),S_N솔루션!K:K,"<="&EOMONTH(DATE(2026,8,1),0))+SUMIFS(특허기술자문료!I:I,특허기술자문료!K:K,">="&DATE(2026,8,1),특허기술자문료!K:K,"<="&EOMONTH(DATE(2026,8,1),0))+SUMPRODUCT((LEFT(자재판매!A2:A500,7)="2026-08")*(자재판매!P2:P500)) -> 0 | M17: =SUMIFS(컨설팅!H:H,컨설팅!L:L,">="&DATE(2026,9,1),컨설팅!L:L,"<="&EOMONTH(DATE(2026,9,1),0))+SUMIFS(S_N솔루션!H:H,S_N솔루션!K:K,">="&DATE(2026,9,1),S_N솔루션!K:K,"<="&EOMONTH(DATE(2026,9,1),0))+SUMIFS(특허기술자문료!I:I,특허기술자문료!K:K,">="&DATE(2026,9,1),특허기술자문료!K:K,"<="&EOMONTH(DATE(2026,9,1),0))+SUMPRODUCT((LEFT(자재판매!A2:A500,7)="2026-09")*(자재판매!P2:P500)) -> 0 | N17: =SUMIFS(컨설팅!H:H,컨설팅!L:L,">="&DATE(2026,10,1),컨설팅!L:L,"<="&EOMONTH(DATE(2026,10,1),0))+SUMIFS(S_N솔루션!H:H,S_N솔루션!K:K,">="&DATE(2026,10,1),S_N솔루션!K:K,"<="&EOMONTH(DATE(2026,10,1),0))+SUMIFS(특허기술자문료!I:I,특허기술자문료!K:K,">="&DATE(2026,10,1),특허기술자문료!K:K,"<="&EOMONTH(DATE(2026,10,1),0))+SUMPRODUCT((LEFT(자재판매!A2:A500,7)="2026-10")*(자재판매!P2:P500)) -> 0 | O17: =SUMIFS(컨설팅!H:H,컨설팅!L:L,">="&DATE(2026,11,1),컨설팅!L:L,"<="&EOMONTH(DATE(2026,11,1),0))+SUMIFS(S_N솔루션!H:H,S_N솔루션!K:K,">="&DATE(2026,11,1),S_N솔루션!K:K,"<="&EOMONTH(DATE(2026,11,1),0))+SUMIFS(특허기술자문료!I:I,특허기술자문료!K:K,">="&DATE(2026,11,1),특허기술자문료!K:K,"<="&EOMONTH(DATE(2026,11,1),0))+SUMPRODUCT((LEFT(자재판매!A2:A500,7)="2026-11")*(자재판매!P2:P500)) -> 0 | P17: =SUMIFS(컨설팅!H:H,컨설팅!L:L,">="&DATE(2026,12,1),컨설팅!L:L,"<="&EOMONTH(DATE(2026,12,1),0))+SUMIFS(S_N솔루션!H:H,S_N솔루션!K:K,">="&DATE(2026,12,1),S_N솔루션!K:K,"<="&EOMONTH(DATE(2026,12,1),0))+SUMIFS(특허기술자문료!I:I,특허기술자문료!K:K,">="&DATE(2026,12,1),특허기술자문료!K:K,"<="&EOMONTH(DATE(2026,12,1),0))+SUMPRODUCT((LEFT(자재판매!A2:A500,7)="2026-12")*(자재판매!P2:P500)) -> 0 | Q17: =SUM(D17:P17) -> 50154600
C23: 3. 카테고리별 매출
C24: 매출구분 | D24: 현장수 | E24: 계약매출 | F24: 확정매출 | G24: 수금예정액 | H24: 관리미수금 | I24: 수금률
C25: 컨설팅 | D25: =MAX(컨설팅!B:B) -> 8 | E25: =SUMIFS(컨설팅!H:H,컨설팅!J:J,">="&DATE(2025,12,1),컨설팅!J:J,"<="&DATE(2026,12,31)) -> 562791000 | F25: =SUMIFS(컨설팅!H:H,컨설팅!L:L,">="&DATE(2025,12,1),컨설팅!L:L,"<="&DATE(2026,12,31)) -> 0 | G25: =SUM(컨설팅!P:P)/1.1 -> 591779000 | H25: =SUMIF(컨설팅!S:S,"확인요망",컨설팅!P:P)/1.1 -> 0 | I25: =IF(F25>0, SUM(컨설팅!O:O)/1.1/F25, 0) -> 0
C26: S/N솔루션 | D26: =MAX(S_N솔루션!B:B) -> 1 | E26: =SUMIFS(S_N솔루션!H:H,S_N솔루션!J:J,">="&DATE(2025,12,1),S_N솔루션!J:J,"<="&DATE(2026,12,31)) -> 0 | F26: =SUMIFS(S_N솔루션!H:H,S_N솔루션!K:K,">="&DATE(2025,12,1),S_N솔루션!K:K,"<="&DATE(2026,12,31)) -> 0 | G26: =SUM(S_N솔루션!O:O)/1.1 -> 0 | H26: =SUMIF(S_N솔루션!P:P,"확인요망",S_N솔루션!O:O)/1.1 -> 0 | I26: =IF(F26>0, SUM(S_N솔루션!N:N)/1.1/F26, 0) -> 0
C27: 특허기술자문료 | D27: =MAX(특허기술자문료!B:B) -> 3 | E27: =SUMIFS(특허기술자문료!I:I,특허기술자문료!J:J,">="&DATE(2025,12,1),특허기술자문료!J:J,"<="&DATE(2026,12,31)) -> 18115600 | F27: =SUMIFS(특허기술자문료!I:I,특허기술자문료!K:K,">="&DATE(2025,12,1),특허기술자문료!K:K,"<="&DATE(2026,12,31)) -> 18115600 | G27: =SUM(특허기술자문료!O:O)/1.1 -> 18115600 | H27: =SUMIF(특허기술자문료!P:P,"확인요망",특허기술자문료!O:O)/1.1 -> 0 | I27: =IF(F27>0, SUM(특허기술자문료!N:N)/1.1/F27, 0) -> 0
C28: 자재판매 | D28: =COUNTA(자재판매!A:A)-1 -> 5 | E28: =SUMPRODUCT((LEFT(자재판매!A2:A500,7)>="2025-12")*(LEFT(자재판매!A2:A500,7)<="2026-12")*(자재판매!P2:P500)) -> 32039000 | F28: =SUMPRODUCT((LEFT(자재판매!A2:A500,7)>="2025-12")*(LEFT(자재판매!A2:A500,7)<="2026-12")*(자재판매!P2:P500)) -> 32039000 | G28: =SUM(자재판매!AK:AK)/1.1 -> 32039000 | H28: =SUMIF(자재판매!AL:AL,"확인요망",자재판매!AK:AK)/1.1 -> 0 | I28: =IF(F28>0, SUM(자재판매!AJ:AJ)/1.1/F28, 0) -> 0
C29: 포어스토어 | D29: - | E29: - | F29: =P40 -> 0 | G29: - | H29: - | I29: -
C30: 그로홈 | D30: - | E30: - | F30: =P41 -> 0 | G30: - | H30: - | I30: -
C31: 모여라딜 | D31: - | E31: - | F31: =P42 -> 0 | G31: - | H31: - | I31: -
C32: 합계 | D32: =SUM(D25:D28) -> 17 | E32: =SUM(E25:E31) -> 612945600 | F32: =SUM(F25:F31) -> 50154600 | G32: =SUM(G25:G31) -> 641933600 | H32: =SUM(H25:H31) -> 0 | I32: =IF(F32>0, (SUM(컨설팅!O:O)+SUM(S_N솔루션!N:N)+SUM(특허기술자문료!N:N)+SUM(자재판매!AJ:AJ))/1.1/F32, 0) -> 0
C34: 4. 카테고리별 월별 매출
C35: 매출구분 | D35: 1월 | E35: 2월 | F35: 3월 | G35: 4월 | H35: 5월 | I35: 6월 | J35: 7월 | K35: 8월 | L35: 9월 | M35: 10월 | N35: 11월 | O35: 12월 | P35: 합계
C36: 컨설팅 | D36: =SUMIFS(컨설팅!H:H,컨설팅!L:L,">="&DATE(2026,1,1),컨설팅!L:L,"<="&EOMONTH(DATE(2026,1,1),0)) -> 0 | E36: =SUMIFS(컨설팅!H:H,컨설팅!L:L,">="&DATE(2026,2,1),컨설팅!L:L,"<="&EOMONTH(DATE(2026,2,1),0)) -> 0 | F36: =SUMIFS(컨설팅!H:H,컨설팅!L:L,">="&DATE(2026,3,1),컨설팅!L:L,"<="&EOMONTH(DATE(2026,3,1),0)) -> 0 | G36: =SUMIFS(컨설팅!H:H,컨설팅!L:L,">="&DATE(2026,4,1),컨설팅!L:L,"<="&EOMONTH(DATE(2026,4,1),0)) -> 0 | H36: =SUMIFS(컨설팅!H:H,컨설팅!L:L,">="&DATE(2026,5,1),컨설팅!L:L,"<="&EOMONTH(DATE(2026,5,1),0)) -> 0 | I36: =SUMIFS(컨설팅!H:H,컨설팅!L:L,">="&DATE(2026,6,1),컨설팅!L:L,"<="&EOMONTH(DATE(2026,6,1),0)) -> 0 | J36: =SUMIFS(컨설팅!H:H,컨설팅!L:L,">="&DATE(2026,7,1),컨설팅!L:L,"<="&EOMONTH(DATE(2026,7,1),0)) -> 0 | K36: =SUMIFS(컨설팅!H:H,컨설팅!L:L,">="&DATE(2026,8,1),컨설팅!L:L,"<="&EOMONTH(DATE(2026,8,1),0)) -> 0 | L36: =SUMIFS(컨설팅!H:H,컨설팅!L:L,">="&DATE(2026,9,1),컨설팅!L:L,"<="&EOMONTH(DATE(2026,9,1),0)) -> 0 | M36: =SUMIFS(컨설팅!H:H,컨설팅!L:L,">="&DATE(2026,10,1),컨설팅!L:L,"<="&EOMONTH(DATE(2026,10,1),0)) -> 0 | N36: =SUMIFS(컨설팅!H:H,컨설팅!L:L,">="&DATE(2026,11,1),컨설팅!L:L,"<="&EOMONTH(DATE(2026,11,1),0)) -> 0 | O36: =SUMIFS(컨설팅!H:H,컨설팅!L:L,">="&DATE(2026,12,1),컨설팅!L:L,"<="&EOMONTH(DATE(2026,12,1),0)) -> 0 | P36: =SUM(D36:O36) -> 0
C37: S/N솔루션 | D37: =SUMIFS(S_N솔루션!H:H,S_N솔루션!K:K,">="&DATE(2026,1,1),S_N솔루션!K:K,"<="&EOMONTH(DATE(2026,1,1),0)) -> 0 | E37: =SUMIFS(S_N솔루션!H:H,S_N솔루션!K:K,">="&DATE(2026,2,1),S_N솔루션!K:K,"<="&EOMONTH(DATE(2026,2,1),0)) -> 0 | F37: =SUMIFS(S_N솔루션!H:H,S_N솔루션!K:K,">="&DATE(2026,3,1),S_N솔루션!K:K,"<="&EOMONTH(DATE(2026,3,1),0)) -> 0 | G37: =SUMIFS(S_N솔루션!H:H,S_N솔루션!K:K,">="&DATE(2026,4,1),S_N솔루션!K:K,"<="&EOMONTH(DATE(2026,4,1),0)) -> 0 | H37: =SUMIFS(S_N솔루션!H:H,S_N솔루션!K:K,">="&DATE(2026,5,1),S_N솔루션!K:K,"<="&EOMONTH(DATE(2026,5,1),0)) -> 0 | I37: =SUMIFS(S_N솔루션!H:H,S_N솔루션!K:K,">="&DATE(2026,6,1),S_N솔루션!K:K,"<="&EOMONTH(DATE(2026,6,1),0)) -> 0 | J37: =SUMIFS(S_N솔루션!H:H,S_N솔루션!K:K,">="&DATE(2026,7,1),S_N솔루션!K:K,"<="&EOMONTH(DATE(2026,7,1),0)) -> 0 | K37: =SUMIFS(S_N솔루션!H:H,S_N솔루션!K:K,">="&DATE(2026,8,1),S_N솔루션!K:K,"<="&EOMONTH(DATE(2026,8,1),0)) -> 0 | L37: =SUMIFS(S_N솔루션!H:H,S_N솔루션!K:K,">="&DATE(2026,9,1),S_N솔루션!K:K,"<="&EOMONTH(DATE(2026,9,1),0)) -> 0 | M37: =SUMIFS(S_N솔루션!H:H,S_N솔루션!K:K,">="&DATE(2026,10,1),S_N솔루션!K:K,"<="&EOMONTH(DATE(2026,10,1),0)) -> 0 | N37: =SUMIFS(S_N솔루션!H:H,S_N솔루션!K:K,">="&DATE(2026,11,1),S_N솔루션!K:K,"<="&EOMONTH(DATE(2026,11,1),0)) -> 0 | O37: =SUMIFS(S_N솔루션!H:H,S_N솔루션!K:K,">="&DATE(2026,12,1),S_N솔루션!K:K,"<="&EOMONTH(DATE(2026,12,1),0)) -> 0 | P37: =SUM(D37:O37) -> 0
C38: 특허기술자문료 | D38: =SUMIFS(특허기술자문료!I:I,특허기술자문료!K:K,">="&DATE(2026,1,1),특허기술자문료!K:K,"<="&EOMONTH(DATE(2026,1,1),0)) -> 18115600 | E38: =SUMIFS(특허기술자문료!I:I,특허기술자문료!K:K,">="&DATE(2026,2,1),특허기술자문료!K:K,"<="&EOMONTH(DATE(2026,2,1),0)) -> 0 | F38: =SUMIFS(특허기술자문료!I:I,특허기술자문료!K:K,">="&DATE(2026,3,1),특허기술자문료!K:K,"<="&EOMONTH(DATE(2026,3,1),0)) -> 0 | G38: =SUMIFS(특허기술자문료!I:I,특허기술자문료!K:K,">="&DATE(2026,4,1),특허기술자문료!K:K,"<="&EOMONTH(DATE(2026,4,1),0)) -> 0 | H38: =SUMIFS(특허기술자문료!I:I,특허기술자문료!K:K,">="&DATE(2026,5,1),특허기술자문료!K:K,"<="&EOMONTH(DATE(2026,5,1),0)) -> 0 | I38: =SUMIFS(특허기술자문료!I:I,특허기술자문료!K:K,">="&DATE(2026,6,1),특허기술자문료!K:K,"<="&EOMONTH(DATE(2026,6,1),0)) -> 0 | J38: =SUMIFS(특허기술자문료!I:I,특허기술자문료!K:K,">="&DATE(2026,7,1),특허기술자문료!K:K,"<="&EOMONTH(DATE(2026,7,1),0)) -> 0 | K38: =SUMIFS(특허기술자문료!I:I,특허기술자문료!K:K,">="&DATE(2026,8,1),특허기술자문료!K:K,"<="&EOMONTH(DATE(2026,8,1),0)) -> 0 | L38: =SUMIFS(특허기술자문료!I:I,특허기술자문료!K:K,">="&DATE(2026,9,1),특허기술자문료!K:K,"<="&EOMONTH(DATE(2026,9,1),0)) -> 0 | M38: =SUMIFS(특허기술자문료!I:I,특허기술자문료!K:K,">="&DATE(2026,10,1),특허기술자문료!K:K,"<="&EOMONTH(DATE(2026,10,1),0)) -> 0 | N38: =SUMIFS(특허기술자문료!I:I,특허기술자문료!K:K,">="&DATE(2026,11,1),특허기술자문료!K:K,"<="&EOMONTH(DATE(2026,11,1),0)) -> 0 | O38: =SUMIFS(특허기술자문료!I:I,특허기술자문료!K:K,">="&DATE(2026,12,1),특허기술자문료!K:K,"<="&EOMONTH(DATE(2026,12,1),0)) -> 0 | P38: =SUM(D38:O38) -> 18115600
C39: 자재판매 | D39: =SUMPRODUCT((LEFT(자재판매!A2:A500,7)="2026-01")*(자재판매!P2:P500)) -> 32039000 | E39: =SUMPRODUCT((LEFT(자재판매!A2:A500,7)="2026-02")*(자재판매!P2:P500)) -> 0 | F39: =SUMPRODUCT((LEFT(자재판매!A2:A500,7)="2026-03")*(자재판매!P2:P500)) -> 0 | G39: =SUMPRODUCT((LEFT(자재판매!A2:A500,7)="2026-04")*(자재판매!P2:P500)) -> 0 | H39: =SUMPRODUCT((LEFT(자재판매!A2:A500,7)="2026-05")*(자재판매!P2:P500)) -> 0 | I39: =SUMPRODUCT((LEFT(자재판매!A2:A500,7)="2026-06")*(자재판매!P2:P500)) -> 0 | J39: =SUMPRODUCT((LEFT(자재판매!A2:A500,7)="2026-07")*(자재판매!P2:P500)) -> 0 | K39: =SUMPRODUCT((LEFT(자재판매!A2:A500,7)="2026-08")*(자재판매!P2:P500)) -> 0 | L39: =SUMPRODUCT((LEFT(자재판매!A2:A500,7)="2026-09")*(자재판매!P2:P500)) -> 0 | M39: =SUMPRODUCT((LEFT(자재판매!A2:A500,7)="2026-10")*(자재판매!P2:P500)) -> 0 | N39: =SUMPRODUCT((LEFT(자재판매!A2:A500,7)="2026-11")*(자재판매!P2:P500)) -> 0 | O39: =SUMPRODUCT((LEFT(자재판매!A2:A500,7)="2026-12")*(자재판매!P2:P500)) -> 0 | P39: =SUM(D39:O39) -> 32039000
C40: 포어스토어 | P40: =SUM(D40:O40) -> 0
C41: 그로홈 | P41: =SUM(D41:O41) -> 0
C42: 모여라딜 | P42: =SUM(D42:O42) -> 0
C43: 월합계 | D43: =SUM(D36:D42) -> 50154600 | E43: =SUM(E36:E42) -> 0 | F43: =SUM(F36:F42) -> 0 | G43: =SUM(G36:G42) -> 0 | H43: =SUM(H36:H42) -> 0 | I43: =SUM(I36:I42) -> 0 | J43: =SUM(J36:J42) -> 0 | K43: =SUM(K36:K42) -> 0 | ... P43: =SUM(P36:P42) -> 50154600

Sheet 컨설팅
B1: 순번 | C1: 매출구분 | D1: 업체명 | E1: 현장명 | F1: 총실행가 | G1: 계약금액(V-) | H1: 매출금액(v-) | I1: 구분 | J1: 계약일 | K1: 착공일 | L1: 매출일 | M1: 입금예정일 | N1: 입금일 | O1: 입금액(V+) | P1: 수금예정액(V+) | Q1: 준공일 | R1: 정산소요일 | S1: 입금지연 | U1: 현장 소장 | V1: 단가 | W1: 노임 금액 | Y1: 추가노무비 | Z1: 안전관리비 | AA1: 장비대금 | AB1: 폐기물 | AC1: 기타 | AD1: 차감총액 | AF1: 자재판매가 | AG1: 컨설팅 순이익금 | AH1: 이익률 | AI1: 자재원가 | AJ1: 이익금액 | AK1: 이익률
B2: 1 | C2: 컨설팅현장 | D2: 에이치제이건설 | E2: 해운대 센텀트루엘 | F2: 83900000 | G2: 59740000 | H2: =G2*20% -> 11948000 | I2: 선금 | J2: 45992 | P2: =(H2*1.1)-O2 -> 13142800 | R2: =IF(AND(J2="잔금", N2<>"", Q2<>""), N2-Q2, "-") -> - | S2: =IF(AND(P2<>"",P2>0,N2="",L2<>""),IF(I2="선금",IF(TODAY()>L2+20,"확인요망","-"),IF(TODAY()>L2+30,"확인요망","-")),"-") -> - | V2: 10000 | W2: 24160000 | AD2: =SUM(Y2:AC2) -> 0 | AF2: 0 | AG2: =G2-AF2 -> 59740000 | AH2: =AG2/F2 -> 0.71203814 | AI2: 0 | AJ2: =G2-AI2 -> 59740000 | AK2: =AJ2/F2 -> 0.71203814
B3: =IF(I2="잔금", B2+1, B2) -> 1 | C3: 컨설팅현장 | D3: =D2 -> 에이치제이건설 | E3: =E2 -> 해운대 센텀트루엘 | H3: =G2*40% -> 23896000 | I3: 중도금 | J3: =J2 -> 45992 | M3: =IF(L3<>"", L3+30, "") | P3: =(H3*1.1)-O3 -> 26285600 | R3: =IF(AND(I3="잔금", N3<>"", Q3<>""), N3-Q3, "-") -> - | S3: =IF(AND(P3<>"",P3>0,N3="",L3<>""),IF(I3="선금",IF(TODAY()>L3+20,"확인요망","-"),IF(TODAY()>L3+30,"확인요망","-")),"-") -> -
B4: =IF(I3="잔금", B3+1, B3) -> 1 | C4: 컨설팅현장 | D4: =D3 -> 에이치제이건설 | E4: =E3 -> 해운대 센텀트루엘 | G4: =-AD2 -> 0 | H4: =(G2*40%)-AD2 -> 23896000 | I4: 잔금 | J4: =J3 -> 45992 | M4: =IF(L4<>"", L4+30, "") | P4: =(H4*1.1)-O4 -> 26285600 | R4: =IF(AND(I4="잔금", N4<>"", Q4<>""), N4-Q4, "-") -> - | S4: =IF(AND(P4<>"",P4>0,N4="",L4<>""),IF(I4="선금",IF(TODAY()>L4+20,"확인요망","-"),IF(TODAY()>L4+30,"확인요망","-")),"-") -> -
B5: =IF(I4="잔금", B4+1, B4) -> 2 | C5: 컨설팅현장 | D5: 여름건설 | E5: 자양10차현대홈타운 | F5: 30420000 | G5: 23001000 | H5: =G5*20% -> 4600200 | I5: 선금 | J5: 45999 | P5: =(H5*1.1)-O5 -> 5060220 | R5: =IF(AND(I5="잔금", N5<>"", Q5<>""), N5-Q5, "-") -> - | S5: =IF(AND(P5<>"",P5>0,N5="",L5<>""),IF(I5="선금",IF(TODAY()>L5+20,"확인요망","-"),IF(TODAY()>L5+30,"확인요망","-")),"-") -> - | W5: 7419000
B6: =IF(I5="잔금", B5+1, B5) -> 2 | C6: 컨설팅현장 | D6: =D5 -> 여름건설 | E6: =E5 -> 자양10차현대홈타운 | H6: =G5*40% -> 9200400 | I6: 중도금 | J6: =J5 -> 45999 | M6: =IF(L6<>"", L6+30, "") | P6: =(H6*1.1)-O6 -> 10120440 | R6: =IF(AND(I6="잔금", N6<>"", Q6<>""), N6-Q6, "-") -> - | S6: =IF(AND(P6<>"",P6>0,N6="",L6<>""),IF(I6="선금",IF(TODAY()>L6+20,"확인요망","-"),IF(TODAY()>L6+30,"확인요망","-")),"-") -> -
B7: =IF(I6="잔금", B6+1, B6) -> 2 | C7: 컨설팅현장 | D7: =D6 -> 여름건설 | E7: =E6 -> 자양10차현대홈타운 | H7: =(G5*40%)-AD5 -> 9200400 | I7: 잔금 | J7: =J6 -> 45999 | M7: =IF(L7<>"", L7+30, "") | P7: =(H7*1.1)-O7 -> 10120440 | R7: =IF(AND(I7="잔금", N7<>"", Q7<>""), N7-Q7, "-") -> - | S7: =IF(AND(P7<>"",P7>0,N7="",L7<>""),IF(I7="선금",IF(TODAY()>L7+20,"확인요망","-"),IF(TODAY()>L7+30,"확인요망","-")),"-") -> -
B8: =IF(I7="잔금", B7+1, B7) -> 3 | C8: 컨설팅현장 | D8: 여름건설 | E8: 광덕파크빌 | F8: 39060000 | G8: 30580000 | H8: =G8*20% -> 6116000 | I8: 선금 | J8: 45999 | M8: =IF(L8<>"", L8+30, "") | P8: =(H8*1.1)-O8 -> 6727600 | R8: =IF(AND(I8="잔금", N8<>"", Q8<>""), N8-Q8, "-") -> - | S8: =IF(AND(P8<>"",P8>0,N8="",L8<>""),IF(I8="선금",IF(TODAY()>L8+20,"확인요망","-"),IF(TODAY()>L8+30,"확인요망","-")),"-") -> - | W8: 8480000
B9: =IF(I8="잔금", B8+1, B8) -> 3 | C9: 컨설팅현장 | D9: =D8 -> 여름건설 | E9: =E8 -> 광덕파크빌 | H9: =G8*40% -> 12232000 | I9: 중도금 | J9: =J8 -> 45999 | M9: =IF(L9<>"", L9+30, "") | P9: =(H9*1.1)-O9 -> 13455200 | R9: =IF(AND(I9="잔금", N9<>"", Q9<>""), N9-Q9, "-") -> - | S9: =IF(AND(P9<>"",P9>0,N9="",L9<>""),IF(I9="선금",IF(TODAY()>L9+20,"확인요망","-"),IF(TODAY()>L9+30,"확인요망","-")),"-") -> -
B10: =IF(I9="잔금", B9+1, B9) -> 3 | C10: 컨설팅현장 | D10: =D9 -> 여름건설 | E10: =E9 -> 광덕파크빌 | H10: =(G8*40%)-AD8 -> 12232000 | I10: 잔금 | J10: =J9 -> 45999 | M10: =IF(L10<>"", L10+30, "") | P10: =(H10*1.1)-O10 -> 13455200 | R10: =IF(AND(I10="잔금", N10<>"", Q10<>""), N10-Q10, "-") -> - | S10: =IF(AND(P10<>"",P10>0,N10="",L10<>""),IF(I10="선금",IF(TODAY()>L10+20,"확인요망","-"),IF(TODAY()>L10+30,"확인요망","-")),"-") -> -
B11: =IF(I10="잔금", B10+1, B10) -> 4 | C11: 컨설팅현장 | D11: 기림이앤씨 | E11: 해누리선경 | F11: 202900000 | G11: =F11-AO11 -> 202900000 | H11: =G11*20% -> 40580000 | I11: 선금 | J11: 45999 | M11: =IF(L11<>"", L11+30, "") | P11: =(H11*1.1)-O11 -> 44638000 | R11: =IF(AND(I11="잔금", N11<>"", Q11<>""), N11-Q11, "-") -> - | S11: =IF(AND(P11<>"",P11>0,N11="",L11<>""),IF(I11="선금",IF(TODAY()>L11+20,"확인요망","-"),IF(TODAY()>L11+30,"확인요망","-")),"-") -> - | W11: 63670000
B12: =IF(I11="잔금", B11+1, B11) -> 4 | C12: 컨설팅현장 | D12: =D11 -> 기림이앤씨 | E12: =E11 -> 해누리선경 | H12: =G11*40% -> 81160000 | I12: 중도금 | J12: =J11 -> 45999 | M12: =IF(L12<>"", L12+30, "") | P12: =(H12*1.1)-O12 -> 89276000 | R12: =IF(AND(I12="잔금", N12<>"", Q12<>""), N12-Q12, "-") -> - | S12: =IF(AND(P12<>"",P12>0,N12="",L12<>""),IF(I12="선금",IF(TODAY()>L12+20,"확인요망","-"),IF(TODAY()>L12+30,"확인요망","-")),"-") -> -
B13: =IF(I12="잔금", B12+1, B12) -> 4 | C13: 컨설팅현장 | D13: =D12 -> 기림이앤씨 | E13: =E12 -> 해누리선경 | H13: =(G11*40%)-AD11 -> 81160000 | I13: 잔금 | J13: =J12 -> 45999 | M13: =IF(L13<>"", L13+30, "") | P13: =(H13*1.1)-O13 -> 89276000 | R13: =IF(AND(I13="잔금", N13<>"", Q13<>""), N13-Q13, "-") -> - | S13: =IF(AND(P13<>"",P13>0,N13="",L13<>""),IF(I13="선금",IF(TODAY()>L13+20,"확인요망","-"),IF(TODAY()>L13+30,"확인요망","-")),"-") -> -
B14: =IF(I13="잔금", B13+1, B13) -> 5 | C14: 컨설팅현장 | D14: 기림이앤씨 | E14: 지웰시티푸르지오1단지오피스텔 | F14: 118400000 | G14: 92300000 | H14: =G14*20% -> 18460000 | I14: 선금 | J14: 45999 | M14: =IF(L14<>"", L14+30, "") | P14: =(H14*1.1)-O14 -> 20306000 | R14: =IF(AND(I14="잔금", N14<>"", Q14<>""), N14-Q14, "-") -> - | S14: =IF(AND(P14<>"",P14>0,N14="",L14<>""),IF(I14="선금",IF(TODAY()>L14+20,"확인요망","-"),IF(TODAY()>L14+30,"확인요망","-")),"-") -> - | W14: 26100000
B15: =IF(I14="잔금", B14+1, B14) -> 5 | C15: 컨설팅현장 | D15: =D14 -> 기림이앤씨 | E15: =E14 -> 지웰시티푸르지오1단지오피스텔 | H15: =G14*40% -> 36920000 | I15: 중도금 | J15: =J14 -> 45999 | M15: =IF(L15<>"", L15+30, "") | P15: =(H15*1.1)-O15 -> 40612000 | R15: =IF(AND(I15="잔금", N15<>"", Q15<>""), N15-Q15, "-") -> - | S15: =IF(AND(P15<>"",P15>0,N15="",L15<>""),IF(I15="선금",IF(TODAY()>L15+20,"확인요망","-"),IF(TODAY()>L15+30,"확인요망","-")),"-") -> -
B16: =IF(I15="잔금", B15+1, B15) -> 5 | C16: 컨설팅현장 | D16: =D15 -> 기림이앤씨 | E16: =E15 -> 지웰시티푸르지오1단지오피스텔 | H16: =(G14*40%)-AD14 -> 36920000 | I16: 잔금 | J16: =J15 -> 45999 | M16: =IF(L16<>"", L16+30, "") | P16: =(H16*1.1)-O16 -> 40612000 | R16: =IF(AND(I16="잔금", N16<>"", Q16<>""), N16-Q16, "-") -> - | S16: =IF(AND(P16<>"",P16>0,N16="",L16<>""),IF(I16="선금",IF(TODAY()>L16+20,"확인요망","-"),IF(TODAY()>L16+30,"확인요망","-")),"-") -> -
B17: =IF(I16="잔금", B16+1, B16) -> 6 | C17: 컨설팅현장 | D17: 건진개발 | E17: 덕천동롯데 | F17: 105000000 | G17: =F17-W17 -> 76200000 | H17: =G17*20% -> 15240000 | I17: 선금 | J17: 45999 | M17: =IF(L17<>"", L17+30, "") | P17: =(H17*1.1)-O17 -> 16764000 | R17: =IF(AND(I17="잔금", N17<>"", Q17<>""), N17-Q17, "-") -> - | S17: =IF(AND(P17<>"",P17>0,N17="",L17<>""),IF(I17="선금",IF(TODAY()>L17+20,"확인요망","-"),IF(TODAY()>L17+30,"확인요망","-")),"-") -> - | W17: 28800000
B18: =IF(I17="잔금", B17+1, B17) -> 6 | C18: 컨설팅현장 | D18: =D17 -> 건진개발 | E18: =E17 -> 덕천동롯데 | H18: =G17*40% -> 30480000 | I18: 중도금 | J18: =J17 -> 45999 | M18: =IF(L18<>"", L18+30, "") | P18: =(H18*1.1)-O18 -> 33528000 | R18: =IF(AND(I18="잔금", N18<>"", Q18<>""), N18-Q18, "-") -> - | S18: =IF(AND(P18<>"",P18>0,N18="",L18<>""),IF(I18="선금",IF(TODAY()>L18+20,"확인요망","-"),IF(TODAY()>L18+30,"확인요망","-")),"-") -> -
B19: =IF(I18="잔금", B18+1, B18) -> 6 | C19: 컨설팅현장 | D19: =D18 -> 건진개발 | E19: =E18 -> 덕천동롯데 | H19: =(G17*40%)-AD17 -> 30480000 | I19: 잔금 | J19: =J18 -> 45999 | M19: =IF(L19<>"", L19+30, "") | P19: =(H19*1.1)-O19 -> 33528000 | R19: =IF(AND(I19="잔금", N19<>"", Q19<>""), N19-Q19, "-") -> - | S19: =IF(AND(P19<>"",P19>0,N19="",L19<>""),IF(I19="선금",IF(TODAY()>L19+20,"확인요망","-"),IF(TODAY()>L19+30,"확인요망","-")),"-") -> -
B20: =IF(I19="잔금", B19+1, B19) -> 7 | C20: 컨설팅현장 | D20: 석민이앤씨 | E20: 동탄역시범한화꿈에그린 프레스티지 | F20: 92100000 | G20: =F20-W20 -> 28988000 | H20: =G20*20% -> 5797600 | I20: 선금 | M20: =IF(L20<>"", L20+30, "") | P20: =(H20*1.1)-O20 -> 6377360 | R20: =IF(AND(I20="잔금", N20<>"", Q20<>""), N20-Q20, "-") -> - | S20: =IF(AND(P20<>"",P20>0,N20="",L20<>""),IF(I20="선금",IF(TODAY()>L20+20,"확인요망","-"),IF(TODAY()>L20+30,"확인요망","-")),"-") -> - | W20: 63112000
B21: =IF(I20="잔금", B20+1, B20) -> 7 | C21: 컨설팅현장 | D21: =D20 -> 석민이앤씨 | E21: =E20 -> 동탄역시범한화꿈에그린 프레스티지 | H21: =G20*40% -> 11595200 | I21: 중도금 | M21: =IF(L21<>"", L21+30, "") | P21: =(H21*1.1)-O21 -> 12754720 | R21: =IF(AND(I21="잔금", N21<>"", Q21<>""), N21-Q21, "-") -> - | S21: =IF(AND(P21<>"",P21>0,N21="",L21<>""),IF(I21="선금",IF(TODAY()>L21+20,"확인요망","-"),IF(TODAY()>L21+30,"확인요망","-")),"-") -> -
B22: =IF(I21="잔금", B21+1, B21) -> 7 | C22: 컨설팅현장 | D22: =D21 -> 석민이앤씨 | E22: =E21 -> 동탄역시범한화꿈에그린 프레스티지 | H22: =(G20*40%)-AD20 -> 11595200 | I22: 잔금 | M22: =IF(L22<>"", L22+30, "") | P22: =(H22*1.1)-O22 -> 12754720 | R22: =IF(AND(I22="잔금", N22<>"", Q22<>""), N22-Q22, "-") -> - | S22: =IF(AND(P22<>"",P22>0,N22="",L22<>""),IF(I22="선금",IF(TODAY()>L22+20,"확인요망","-"),IF(TODAY()>L22+30,"확인요망","-")),"-") -> -
B23: =IF(I22="잔금", B22+1, B22) -> 8 | C23: 컨설팅현장 | D23: 색채산업개발 | E23: 토당금강KCC | F23: 101700000 | G23: =F23-W23 -> 78070000 | H23: =G23*20% -> 15614000 | I23: 선금 | J23: 46009 | M23: =IF(L23<>"", L23+30, "") | P23: =(H23*1.1)-O23 -> 17175400 | R23: =IF(AND(I23="잔금", N23<>"", Q23<>""), N23-Q23, "-") -> - | S23: =IF(AND(P23<>"",P23>0,N23="",L23<>""),IF(I23="선금",IF(TODAY()>L23+20,"확인요망","-"),IF(TODAY()>L23+30,"확인요망","-")),"-") -> - | W23: 23630000
B24: =IF(I23="잔금", B23+1, B23) -> 8 | C24: 컨설팅현장 | D24: =D23 -> 색채산업개발 | E24: =E23 -> 토당금강KCC | H24: =G23*40% -> 31228000 | I24: 중도금 | J24: =J23 -> 46009 | M24: =IF(L24<>"", L24+30, "") | P24: =(H24*1.1)-O24 -> 34350800 | R24: =IF(AND(I24="잔금", N24<>"", Q24<>""), N24-Q24, "-") -> - | S24: =IF(AND(P24<>"",P24>0,N24="",L24<>""),IF(I24="선금",IF(TODAY()>L24+20,"확인요망","-"),IF(TODAY()>L24+30,"확인요망","-")),"-") -> -
B25: =IF(I24="잔금", B24+1, B24) -> 8 | C25: 컨설팅현장 | D25: =D24 -> 색채산업개발 | E25: =E24 -> 토당금강KCC | H25: =(G23*40%)-AD23 -> 31228000 | I25: 잔금 | J25: =J24 -> 46009 | M25: =IF(L25<>"", L25+30, "") | P25: =(H25*1.1)-O25 -> 34350800 | R25: =IF(AND(I25="잔금", N25<>"", Q25<>""), N25-Q25, "-") -> - | S25: =IF(AND(P25<>"",P25>0,N25="",L25<>""),IF(I25="선금",IF(TODAY()>L25+20,"확인요망","-"),IF(TODAY()>L25+30,"확인요망","-")),"-") -> -
M26: =IF(L26<>"", L26+30, "") | S26: =IF(AND(P26<>"",P26>0,N26="",L26<>""),IF(I26="선금",IF(TODAY()>L26+20,"확인요망","-"),IF(TODAY()>L26+30,"확인요망","-")),"-") -> -
M27: =IF(L27<>"", L27+30, "") | S27: =IF(AND(P27<>"",P27>0,N27="",L27<>""),IF(I27="선금",IF(TODAY()>L27+20,"확인요망","-"),IF(TODAY()>L27+30,"확인요망","-")),"-") -> -
M28: =IF(L28<>"", L28+30, "") | S28: =IF(AND(P28<>"",P28>0,N28="",L28<>""),IF(I28="선금",IF(TODAY()>L28+20,"확인요망","-"),IF(TODAY()>L28+30,"확인요망","-")),"-") -> -
M29: =IF(L29<>"", L29+30, "") | S29: =IF(AND(P29<>"",P29>0,N29="",L29<>""),IF(I29="선금",IF(TODAY()>L29+20,"확인요망","-"),IF(TODAY()>L29+30,"확인요망","-")),"-") -> -
M30: =IF(L30<>"", L30+30, "") | S30: =IF(AND(P30<>"",P30>0,N30="",L30<>""),IF(I30="선금",IF(TODAY()>L30+20,"확인요망","-"),IF(TODAY()>L30+30,"확인요망","-")),"-") -> -
M31: =IF(L31<>"", L31+30, "") | S31: =IF(AND(P31<>"",P31>0,N31="",L31<>""),IF(I31="선금",IF(TODAY()>L31+20,"확인요망","-"),IF(TODAY()>L31+30,"확인요망","-")),"-") -> -
M32: =IF(L32<>"", L32+30, "") | S32: =IF(AND(P32<>"",P32>0,N32="",L32<>""),IF(I32="선금",IF(TODAY()>L32+20,"확인요망","-"),IF(TODAY()>L32+30,"확인요망","-")),"-") -> -
M33: =IF(L33<>"", L33+30, "") | S33: =IF(AND(P33<>"",P33>0,N33="",L33<>""),IF(I33="선금",IF(TODAY()>L33+20,"확인요망","-"),IF(TODAY()>L33+30,"확인요망","-")),"-") -> -
M34: =IF(L34<>"", L34+30, "") | S34: =IF(AND(P34<>"",P34>0,N34="",L34<>""),IF(I34="선금",IF(TODAY()>L34+20,"확인요망","-"),IF(TODAY()>L34+30,"확인요망","-")),"-") -> -
M35: =IF(L35<>"", L35+30, "") | S35: =IF(AND(P35<>"",P35>0,N35="",L35<>""),IF(I35="선금",IF(TODAY()>L35+20,"확인요망","-"),IF(TODAY()>L35+30,"확인요망","-")),"-") -> -
M36: =IF(L36<>"", L36+30, "") | S36: =IF(AND(P36<>"",P36>0,N36="",L36<>""),IF(I36="선금",IF(TODAY()>L36+20,"확인요망","-"),IF(TODAY()>L36+30,"확인요망","-")),"-") -> -
M37: =IF(L37<>"", L37+30, "") | S37: =IF(AND(P37<>"",P37>0,N37="",L37<>""),IF(I37="선금",IF(TODAY()>L37+20,"확인요망","-"),IF(TODAY()>L37+30,"확인요망","-")),"-") -> -
... M87: =IF(L87<>"", L87+30, "") | S87: =IF(AND(P87<>"",P87>0,N87="",L87<>""),IF(I87="선금",IF(TODAY()>L87+20,"확인요망","-"),IF(TODAY()>L87+30,"확인요망","-")),"-") -> -

Sheet S_N솔루션
B1: 순번 | C1: 매출구분 | D1: 업체명 | E1: 현장명 | F1: 낙찰금액(v-) | G1: 계약금액(v-) | H1: 매출금액(v-) | I1: 구분 | J1: 계약일 | K1: 매출일 | L1: 입금예정일 | M1: 입금일 | N1: 입금액(V+) | O1: 수금예정액(V+) | P1: 입금지연
B2: 1 | C2: S/N솔루션 | H2: =G2 -> 0 | L2: =IF(K2<>"", K2+30, "") | O2: =(H2*1.1)-N2 -> 0 | P2: =IF(AND(O2<>"",O2>0,M2="",K2<>""),IF(I2="선금",IF(TODAY()>K2+20,"확인요망","-"),IF(TODAY()>K2+30,"확인요망","-")),"-") -> -
B3: =IF(I2="잔금", B2+1, B2) -> 1 | C3: S/N솔루션 | H3: =G3*40% -> 0 | L3: =IF(K3<>"", K3+30, "") | O3: =(H3*1.1)-N3 -> 0 | P3: =IF(AND(O3<>"",O3>0,M3="",K3<>""),IF(I3="선금",IF(TODAY()>K3+20,"확인요망","-"),IF(TODAY()>K3+30,"확인요망","-")),"-") -> -

Sheet 특허기술자문료
B1: 순번 | C1: 매출구분 | D1: 업체명 | E1: 현장명 | F1: 낙찰금액(v-) | G1: 특허료 비율 | H1: 자재판매(v-) | I1: 매출액(v-) | J1: 공문발송일 | K1: 매출일 | L1: 입금예정일 | M1: 입금일 | N1: 입금액(v+) | O1: 수금예정액(V+) | P1: 입금지연
B2: 1 | C2: 특허기술자문료 | D2: (주)효덕산업 | E2: 신정현대6차 아파트 | F2: 396000000 | G2: 0.01 | H2: 315000 | I2: =(F2*G2)-(H2*50%) -> 3802500 | J2: 45999 | K2: 46027 | L2: =IF(K2<>"", K2+30, "") -> 46057 | O2: =(I2*1.1)-N2 -> 4182750 | P2: =IF(AND(O2<>"",O2>0,M2="",K2<>"",TODAY()>K2+30),"확인요망","-") -> -
B3: 2 | C3: 특허기술자문료 | D3: 석진건설(주) | E3: 포레나광교상현아파트 | F3: 809200000 | G3: 0.01 | H3: 15907900 | I3: =(F3*G3)-(H3*50%) -> 138050 | J3: 46020 | K3: 46028 | L3: =IF(K3<>"", K3+30, "") -> 46058 | O3: =(I3*1.1)-N3 -> 151855 | P3: =IF(AND(O3<>"",O3>0,M3="",K3<>"",TODAY()>K3+30),"확인요망","-") -> -
B4: 3 | C4: 특허기술자문료 | D4: 석진건설(주) | E4: 동탄역더샵센트럴시티2차아파트 | F4: 830000000 | G4: 0.01 | H4: 3249900 | I4: =(F4*G4)-(H4*50%) -> 6675050 | J4: 46020 | K4: 46028 | L4: =IF(K4<>"", K4+30, "") -> 46058 | O4: =(I4*1.1)-N4 -> 7342555 | P4: =IF(AND(O4<>"",O4>0,M4="",K4<>"",TODAY()>K4+30),"확인요망","-") -> -
B5: 3 | C5: 특허기술자문료 | D5: (주)청명이앤디 | E5: 영주동 도경오벨리스아파트 | I5: 7500000 | J5: 46020 | K5: 46028 | L5: =IF(K5<>"", K5+30, "") -> 46058 | O5: =(I5*1.1)-N5 -> 8250000 | P5: =IF(AND(O5<>"",O5>0,M5="",K5<>"",TODAY()>K5+30),"확인요망","-") -> -

Sheet 자재판매
A1: 매출일 | B1: 승인번호 | C1: 발급일자 | D1: 전송일자 | E1: 공급자사업자등록번호 | F1: 종사업장번호 | G1: 상호 | H1: 대표자명 | I1: 주소 | J1: 공급받는자사업자등록번호 | K1: 종사업장번호 | L1: 업체명 | M1: 대표자명 | N1: 주소 | O1: 합계금액 | P1: 매출액(v-) | Q1: 세액 | R1: 전자세금계산서분류 | T1: 발급유형 | U1: 비고 | V1: 영수/청구 구분 | W1: 공급자 이메일 | X1: 공급받는자 이메일1 | Y1: 공급받는자 이메일2 | Z1: 품목일자 | AA1: 품목명 | AB1: 품목규격 | AC1: 품목수량 | AD1: 품목단가 | AE1: 품목공급가액 | AF1: 품목세액 | AG1: 현장명 | AH1: 입금예정일 | AI1: 입금일 | AJ1: 입금액(v+) | AK1: 수금예정액(V+) | AL1: 입금지연
A2: 2026-01-05 | B2: 20260105-10260105-90287761 | C2: 2026-01-05 | D2: 2026-01-05 | E2: 403-81-84528 | G2: 주식회사 넷폼알앤디(NETFORM R&D Corp.) | H2: 이승우 | I2: 경기도 오산시 서동로 77, 1층,3층(서동) | J2: 416-81-21999 | L2: (주)부영씨엔씨 | M2: 정동진 | N2: 서울특별시 광진구 자양동 784-1 대동상가동 107 | O2: 28800200 | P2: 26182000 | Q2: 2618200 | R2: 세금계산서 | T2: 인터넷발급 | U2: 기업은행 468-084895-04-017 넷폼알앤디 | V2: 청구 | W2: netform@netformrnd.com | X2: booyoung458@hanmail.net | Z2: 2026-01-05 | AA2: 자재대금 | AC2: 1 | AD2: 26,182,000 | AE2: 26182000 | AF2: 2618200 | AG2: 잠실리센츠 | AH2: =IF(A2<>"", A2+30, "") -> 46057 | AK2: =(P2*1.1)-AJ2 -> 28800200 | AL2: =IF(AND(AK2<>"",AK2>0,AI2="",A2<>"",TODAY()>A2+40),"확인요망","-") -> -
A3: 2026-01-05 | B3: 20260105-10260105-90284342 | C3: 2026-01-05 | D3: 2026-01-05 | E3: 403-81-84528 | G3: 주식회사 넷폼알앤디(NETFORM R&D Corp.) | H3: 이승우 | I3: 경기도 오산시 서동로 77, 1층,3층(서동) | J3: 579-87-01622 | L3: (주)에이치제이건설 | M3: 노옥분 | N3: 경상남도 양산시 물금읍 야리3길 34, 부광타워 607 | O3: 1210000 | P3: 1100000 | Q3: 110000 | R3: 세금계산서 | T3: 인터넷발급 | U3: 기업은행 468-084895-04-017 넷폼알앤디 | V3: 청구 | W3: netform@netformrnd.com | X3: hj202002@naver.com | Z3: 2026-01-05 | AA3: 자재대금 | AC3: 1 | AD3: 1,100,000 | AE3: 1100000 | AF3: 110000 | AG3: 양산유탑유블레스 | AH3: =IF(A3<>"", A3+30, "") -> 46057 | AK3: =(P3*1.1)-AJ3 -> 1210000 | AL3: =IF(AND(AK3<>"",AK3>0,AI3="",A3<>"",TODAY()>A3+40),"확인요망","-") -> -
A4: 2026-01-06 | B4: 20260106-10260106-92182686 | C4: 2026-01-06 | D4: 2026-01-06 | E4: 403-81-84528 | G4: 주식회사 넷폼알앤디(NETFORM R&D Corp.) | H4: 이승우 | I4: 경기도 오산시 서동로 77, 1층,3층(서동) | J4: 416-81-21999 | L4: (주)부영씨엔씨 | M4: 정동진 | N4: 서울특별시 광진구 자양동 784-1 대동상가동 107 | O4: 878900 | P4: 799000 | Q4: 79900 | R4: 세금계산서 | T4: 인터넷발급 | U4: 기업은행 468-084895-04-017 넷폼알앤디 | V4: 청구 | W4: netform@netformrnd.com | X4: booyoung458@hanmail.net | Z4: 2026-01-06 | AA4: 자재대금 | AC4: 1 | AD4: 799,000 | AE4: 799000 | AF4: 79900 | AG4: 잠실리센츠 | AH4: =IF(A4<>"", A4+30, "") -> 46058 | AK4: =(P4*1.1)-AJ4 -> 878900 | AL4: =IF(AND(AK4<>"",AK4>0,AI4="",A4<>"",TODAY()>A4+40),"확인요망","-") -> -
A5: 2026-01-06 | B5: 20260106-10260106-91528242 | C5: 2026-01-06 | D5: 2026-01-06 | E5: 403-81-84528 | G5: 주식회사 넷폼알앤디(NETFORM R&D Corp.) | H5: 이승우 | I5: 경기도 오산시 서동로 77, 1층,3층(서동) | J5: 607-81-44583 | L5: (주)대한진단건설 | M5: 이헌재 | N5: 부산광역시 동래구 사직북로63번길 55 | O5: 3773000 | P5: 3430000 | Q5: 343000 | R5: 세금계산서 | T5: 인터넷발급 | U5: 기업은행 468-084895-04-017 넷폼알앤디 | V5: 청구 | W5: netform@netformrnd.com | X5: daehan0404@nate.com | Z5: 2026-01-06 | AA5: 자재대금 | AC5: 1 | AD5: 3,430,000 | AE5: 3430000 | AF5: 343000 | AG5: 더샵센텀파크1차 | AH5: =IF(A5<>"", A5+30, "") -> 46058 | AK5: =(P5*1.1)-AJ5 -> 3773000 | AL5: =IF(AND(AK5<>"",AK5>0,AI5="",A5<>"",TODAY()>A5+40),"확인요망","-") -> -
A6: 2026-01-08 | B6: 20260108-10260108-95917215 | C6: 2026-01-08 | D6: 2026-01-08 | E6: 403-81-84528 | G6: 주식회사 넷폼알앤디(NETFORM R&D Corp.) | H6: 이승우 | I6: 경기도 오산시 서동로 77, 1층,3층(서동) | J6: 408-81-67484 | L6: 정광이엔씨 | M6: 박성배 | N6: 서울특별시 광진구 뚝섬로31길 11(자양동,2층) | O6: 580800 | P6: 528000 | Q6: 52800 | R6: 세금계산서 | S6: 일반 | T6: 인터넷발급 | U6: 기업은행 468-084895-04-017 넷폼알앤디 | V6: 청구 | W6: netform@netformrnd.com | X6: jungyoon0343@hanmail.net | Z6: 2026-01-08 | AA6: 자재대금 | AC6: 1 | AD6: 528,000 | AE6: 528000 | AF6: 52800 | AG6: 경동 안성공도만정626 | AH6: =IF(A6<>"", A6+30, "") -> 46060 | AK6: =(P6*1.1)-AJ6 -> 580800 | AL6: =IF(AND(AK6<>"",AK6>0,AI6="",A6<>"",TODAY()>A6+40),"확인요망","-") -> -
AH7: =IF(A7<>"", A7+30, "") | AK7: =(P7*1.1)-AJ7 -> 0 | AL7: =IF(AND(AK7<>"",AK7>0,AI7="",A7<>"",TODAY()>A7+40),"확인요망","-") -> -
AH8: =IF(A8<>"", A8+30, "") | AK8: =(P8*1.1)-AJ8 -> 0 | AL8: =IF(AND(AK8<>"",AK8>0,AI8="",A8<>"",TODAY()>A8+40),"확인요망","-") -> -
AH9: =IF(A9<>"", A9+30, "") | AK9: =(P9*1.1)-AJ9 -> 0 | AL9: =IF(AND(AK9<>"",AK9>0,AI9="",A9<>"",TODAY()>A9+40),"확인요망","-") -> -
AH10: =IF(A10<>"", A10+30, "") | AK10: =(P10*1.1)-AJ10 -> 0 | AL10: =IF(AND(AK10<>"",AK10>0,AI10="",A10<>"",TODAY()>A10+40),"확인요망","-") -> -
AH11: =IF(A11<>"", A11+30, "") | AK11: =(P11*1.1)-AJ11 -> 0 | AL11: =IF(AND(AK11<>"",AK11>0,AI11="",A11<>"",TODAY()>A11+40),"확인요망","-") -> -
AH12: =IF(A12<>"", A12+30, "") | AK12: =(P12*1.1)-AJ12 -> 0 | AL12: =IF(AND(AK12<>"",AK12>0,AI12="",A12<>"",TODAY()>A12+40),"확인요망","-") -> -
AH13: =IF(A13<>"", A13+30, "") | AK13: =(P13*1.1)-AJ13 -> 0 | AL13: =IF(AND(AK13<>"",AK13>0,AI13="",A13<>"",TODAY()>A13+40),"확인요망","-") -> -
AH14: =IF(A14<>"", A14+30, "") | AK14: =(P14*1.1)-AJ14 -> 0 | AL14: =IF(AND(AK14<>"",AK14>0,AI14="",A14<>"",TODAY()>A14+40),"확인요망","-") -> -
AH15: =IF(A15<>"", A15+30, "") | AK15: =(P15*1.1)-AJ15 -> 0 | AL15: =IF(AND(AK15<>"",AK15>0,AI15="",A15<>"",TODAY()>A15+40),"확인요망","-") -> -
AH16: =IF(A16<>"", A16+30, "") | AK16: =(P16*1.1)-AJ16 -> 0 | AL16: =IF(AND(AK16<>"",AK16>0,AI16="",A16<>"",TODAY()>A16+40),"확인요망","-") -> -
AH17: =IF(A17<>"", A17+30, "") | AK17: =(P17*1.1)-AJ17 -> 0 | AL17: =IF(AND(AK17<>"",AK17>0,AI17="",A17<>"",TODAY()>A17+40),"확인요망","-") -> -
AH18: =IF(A18<>"", A18+30, "") | AK18: =(P18*1.1)-AJ18 -> 0 | AL18: =IF(AND(AK18<>"",AK18>0,AI18="",A18<>"",TODAY()>A18+40),"확인요망","-") -> -
AH19: =IF(A19<>"", A19+30, "") | AK19: =(P19*1.1)-AJ19 -> 0 | AL19: =IF(AND(AK19<>"",AK19>0,AI19="",A19<>"",TODAY()>A19+40),"확인요망","-") -> -
AH20: =IF(A20<>"", A20+45, "") | AK20: =(P20*1.1)-AJ20 -> 0 | AL20: =IF(AND(AK20<>"",AK20>0,AI20="",A20<>"",TODAY()>A20+40),"확인요망","-") -> -
AH21: =IF(A21<>"", A21+45, "") | AK21: =(P21*1.1)-AJ21 -> 0 | AL21: =IF(AND(AK21<>"",AK21>0,AI21="",A21<>"",TODAY()>A21+40),"확인요망","-") -> -
AH22: =IF(A22<>"", A22+45, "") | AK22: =(P22*1.1)-AJ22 -> 0 | AL22: =IF(AND(AK22<>"",AK22>0,AI22="",A22<>"",TODAY()>A22+40),"확인요망","-") -> -
AH23: =IF(A23<>"", A23+45, "") | AK23: =(P23*1.1)-AJ23 -> 0 | AL23: =IF(AND(AK23<>"",AK23>0,AI23="",A23<>"",TODAY()>A23+40),"확인요망","-") -> -
AH24: =IF(A24<>"", A24+45, "") | AK24: =(P24*1.1)-AJ24 -> 0 | AL24: =IF(AND(AK24<>"",AK24>0,AI24="",A24<>"",TODAY()>A24+40),"확인요망","-") -> -
AH25: =IF(A25<>"", A25+45, "") | AK25: =(P25*1.1)-AJ25 -> 0 | AL25: =IF(AND(AK25<>"",AK25>0,AI25="",A25<>"",TODAY()>A25+40),"확인요망","-") -> -
AH26: =IF(A26<>"", A26+45, "") | AK26: =(P26*1.1)-AJ26 -> 0 | AL26: =IF(AND(AK26<>"",AK26>0,AI26="",A26<>"",TODAY()>A26+40),"확인요망","-") -> -
AH27: =IF(A27<>"", A27+45, "") | AK27: =(P27*1.1)-AJ27 -> 0 | AL27: =IF(AND(AK27<>"",AK27>0,AI27="",A27<>"",TODAY()>A27+40),"확인요망","-") -> -
AH28: =IF(A28<>"", A28+45, "") | AK28: =(P28*1.1)-AJ28 -> 0 | AL28: =IF(AND(AK28<>"",AK28>0,AI28="",A28<>"",TODAY()>A28+40),"확인요망","-") -> -
AH29: =IF(A29<>"", A29+45, "") | AK29: =(P29*1.1)-AJ29 -> 0 | AL29: =IF(AND(AK29<>"",AK29>0,AI29="",A29<>"",TODAY()>A29+40),"확인요망","-") -> -
AH30: =IF(A30<>"", A30+45, "") | AK30: =(P30*1.1)-AJ30 -> 0 | AL30: =IF(AND(AK30<>"",AK30>0,AI30="",A30<>"",TODAY()>A30+40),"확인요망","-") -> -
AH31: =IF(A31<>"", A31+45, "") | AK31: =(P31*1.1)-AJ31 -> 0 | AL31: =IF(AND(AK31<>"",AK31>0,AI31="",A31<>"",TODAY()>A31+40),"확인요망","-") -> -
... AH34: =IF(A34<>"", A34+45, "") | AK34: =(P34*1.1)-AJ34 -> 0 | AL34: =IF(AND(AK34<>"",AK34>0,AI34="",A34<>"",TODAY()>A34+40),"확인요망","-") -> -

Sheet 2025현장 미수금관리
A3: 1. 컨설팅 매출 | G3: 선급금 | L3: 1차 중도금 | Q3: 2차 중도금 | W3: 잔금 | AJ3: 노임 | AN3: 차감내역 | AR3: 차감총액 | AW3: 자재 금액 - 판매 | AZ3: 자재 금액 - 원가
A4: 순 번 | B4: 착공일 | C4: 업체명 | D4: 현장명 | E4: 총실행가 | F4: 컨설팅 금액 | G4: 금액 | H4: 발행 | I4: 예정 | J4: 입금 | K4: 미수금액 | L4: 금액2 | M4: 발행3 | N4: 예정4 | O4: 입금5 | P4: 미수금액6 | Q4: 금액7 | R4: 발행8 | S4: 예정9 | T4: 입금10 | U4: 미수금액11 | V4: 중간 수금액 | W4: 금액12 | X4: 차감액 | Y4: 최종잔금 | Z4: 준공일 (A) | AA4: 발행13 | AB4: 예정14 | AC4: 입금 (B) | AD4: 정산 지연일 (A-B) | AE4: 미수금액2 | AF4: 최종수금액 | AG4: 미수금액 (계산서발행o) | AH4: 계산서 미발행액 | AJ4: 현장 소장 | AK4: 단가 | AL4: 노임 금액 | AM4: 추가노무비 | AN4: 안전관리비 | AO4: 장비대금 | AP4: 폐기물 | AQ4: 기타 | AW4: 자재 총액 | AX4: 이익금액 | AY4: 이익률 | AZ4: 자재 총액 | BA4: 이익금액 | BB4: 이익률
A5: 1 | B5: 45930 | C5: 일성기업 | D5: 산격대우 | E5: 239000000 | F5: =E5-AL5 -> 154976000 | G5: =F5*20% -> 30995200 | H5: 45930 | I5: 45945 | J5: 45959 | K5: =IF(COUNT(J5),0,G5) -> 0 | L5: =F5*40% -> 61990400 | M5: 45978 | N5: 46006 | O5: 46000 | P5: =IF(COUNT(O5),0,L5) -> 0 | U5: =IF(COUNT(T5),0,Q5) -> 0 | V5: =표1_3[[#This Row],[금액]]+표1_3[[#This Row],[금액2]] -> 92985600 | W5: =F5*40% -> 61990400 | X5: =AR5 -> 20752000 | Y5: =W5-X5 -> 41238400 | Z5: 46000 | AA5: 46022 | AB5: 46037 | AE5: =IF(COUNT(AC5),0,Y5) -> 41238400 | AG5: =(K5+P5+표1_3[[#This Row],[미수금액2]])-AH5 -> 41238400 | AH5: =SUM(IF(COUNTBLANK(H5),G5,0),IF(COUNTBLANK(M5),L5,0),IF(COUNTBLANK(AA5),Y5,0)) -> 0 | AJ5: 정상혁/신현섭 | AK5: 12000 | AL5: 84024000 | AM5: 19252000 | AP5: 1500000 | AR5: =SUM(AM5:AQ5) -> 20752000 | AW5: 120267500 | AX5: =표1_3[[#This Row],[총실행가]]-AL5-AR5-AW5 -> 13956500 | AY5: =AX5/표1_3[[#This Row],[총실행가]] -> 0.058395397 | AZ5: 50186700 | BA5: =표1_3[[#This Row],[총실행가]]-AL5-AR5-AZ5 -> 84037300 | BB5: =BA5/표1_3[[#This Row],[총실행가]] -> 0.3516205
A6: 2 | B6: 45944 | C6: 한국전문건설 | D6: 이편한세상화랑대 | E6: =189500000+9500000 -> 199000000 | F6: =E6-AL6 -> 130228000 | G6: 36218400 | H6: 45945 | I6: 45961 | J6: 46022 | K6: =IF(COUNT(J6),0,G6) -> 0 | L6: 48291200 | M6: 45980 | N6: 45989 | P6: =IF(COUNT(O6),0,L6) -> 48291200 | U6: =IF(COUNT(T6),0,Q6) -> 0 | V6: =표1_3[[#This Row],[금액]] -> 36218400 | W6: =표1_3[[#This Row],[컨설팅 금액]]-표1_3[[#This Row],[금액]]-표1_3[[#This Row],[금액2]] -> 45718400 | X6: =AR6 -> 7479000 | Y6: =W6-X6 -> 38239400 | Z6: 46002 | AA6: 46015 | AB6: 46022 | AE6: =IF(COUNT(AC6),0,Y6) -> 38239400 | AG6: =(K6+P6+표1_3[[#This Row],[미수금액2]])-AH6 -> 86530600 | AH6: =SUM(IF(COUNTBLANK(H6),G6,0),IF(COUNTBLANK(M6),L6,0),IF(COUNTBLANK(AA6),Y6,0)) -> 0 | AJ6: 백우현/윤성환 | AK6: 11000 | AL6: =6252*AK6 -> 68772000 | AM6: 5199000 | AP6: 2280000 | AR6: =SUM(AM6:AQ6) -> 7479000 | AW6: 102243400 | AX6: =표1_3[[#This Row],[총실행가]]-AL6-AR6-AW6 -> 20505600 | AY6: =AX6/표1_3[[#This Row],[총실행가]] -> 0.10304322 | AZ6: 53829300 | BA6: =표1_3[[#This Row],[총실행가]]-AL6-AR6-AZ6 -> 68919700 | BB6: =BA6/표1_3[[#This Row],[총실행가]] -> 0.34633015
A7: 3 | B7: 45946 | C7: 엘케이개발 | D7: 율전삼성2단지 | E7: =131600000+8000000 -> 139600000 | F7: =E7-AL7 -> 83824000 | G7: 15164800 | H7: 45954 | I7: 45976 | J7: 45996 | K7: =IF(COUNT(J7),0,G7) -> 0 | L7: 30329600 | M7: 45975 | N7: 45989 | O7: 45996 | P7: =IF(COUNT(O7),0,L7) -> 0 | Q7: 23731600 | R7: 46006 | T7: 46015 | U7: =IF(COUNT(T7),0,Q7) -> 0 | V7: =표1_3[[#This Row],[금액]]+표1_3[[#This Row],[금액2]]+표1_3[[#This Row],[금액7]] -> 69226000 | W7: =표1_3[[#This Row],[컨설팅 금액]]-표1_3[[#This Row],[금액]]-표1_3[[#This Row],[금액2]] -> 38329600 | X7: =AR7 -> 8598000 | Y7: =W7-X7-표1_3[[#This Row],[금액7]] -> 6000000 | Z7: 45992 | AA7: 46006 | AB7: 46022 | AE7: =IF(COUNT(AC7),0,Y7) -> 6000000 | AG7: =(K7+P7+표1_3[[#This Row],[미수금액2]])-AH7 -> 6000000 | AH7: =SUM(IF(COUNTBLANK(H7),G7,0),IF(COUNTBLANK(M7),L7,0),IF(COUNTBLANK(AA7),Y7,0)) -> 0 | AJ7: 이용암 | AK7: 12000 | AL7: 55776000 | AM7: 6898000 | AO7: 1000000 | AP7: 700000 | AR7: 8598000 | AW7: 48873800 | AX7: =표1_3[[#This Row],[총실행가]]-AL7-AR7-AW7 -> 26352200 | AY7: =AX7/표1_3[[#This Row],[총실행가]] -> 0.18876934 | AZ7: 22514200 | BA7: =표1_3[[#This Row],[총실행가]]-AL7-AR7-AZ7 -> 52711800 | BB7: =BA7/표1_3[[#This Row],[총실행가]] -> 0.37759169
A8: 4 | B8: 45965 | C8: 도경 | D8: 광명 | E8: 93600000 | F8: =E8-AL8 -> 46100000 | G8: =F8*20% -> 9220000 | H8: 45966 | I8: 45976 | J8: 45975 | K8: =IF(COUNT(J8),0,G8) -> 0 | L8: =F8*40% -> 18440000 | M8: 45986 | N8: 46006 | O8: 46006 | P8: =IF(COUNT(O8),0,L8) -> 0 | U8: =IF(COUNT(T8),0,Q8) -> 0 | V8: =표1_3[[#This Row],[금액]]+표1_3[[#This Row],[금액2]] -> 27660000 | W8: =F8*40% -> 18440000 | X8: =AR8 -> 4050000 | Y8: =W8-X8 -> 14390000 | Z8: 45992 | AA8: 46002 | AB8: 46022 | AE8: =IF(COUNT(AC8),0,Y8) -> 14390000 | AG8: =(K8+P8+표1_3[[#This Row],[미수금액2]])-AH8 -> 14390000 | AH8: =SUM(IF(COUNTBLANK(H8),G8,0),IF(COUNTBLANK(M8),L8,0),IF(COUNTBLANK(AA8),Y8,0)) -> 0 | AJ8: 김원규 | AK8: 옥탑 190만원 | AL8: 47500000 | AO8: 1200000 | AP8: 2850000 | AR8: 4050000 | AW8: 24030000 | AX8: =표1_3[[#This Row],[총실행가]]-AL8-AR8-AW8 -> 18020000 | AY8: =AX8/표1_3[[#This Row],[총실행가]] -> 0.19252137 | AZ8: 12067300 | BA8: =표1_3[[#This Row],[총실행가]]-AL8-AR8-AZ8 -> 29982700 | BB8: =BA8/표1_3[[#This Row],[총실행가]] -> 0.32032799
A9: 5 | B9: 45973 | C9: 혜성씨앤씨 | D9: 호계신성미소지움 | E9: 105000000 | F9: =E9-AL9 -> 56686000 | G9: 13387200 | H9: 45973 | I9: 45989 | J9: 46006 | K9: =IF(COUNT(J9),0,G9) -> 0 | L9: 13750000 | M9: 46007 | N9: 46052 | P9: =IF(COUNT(O9),0,L9) -> 13750000 | U9: =IF(COUNT(T9),0,Q9) -> 0 | V9: =표1_3[[#This Row],[금액]] -> 13387200 | W9: 29548800 | X9: =AR9 -> 14950000 | Y9: =W9-X9 -> 14598800 | Z9: 46009 | AA9: 46015 | AB9: 46052 | AE9: =IF(COUNT(AC9),0,Y9) -> 14598800 | AG9: =(K9+P9+표1_3[[#This Row],[미수금액2]])-AH9 -> 28348800 | AH9: =SUM(IF(COUNTBLANK(H9),G9,0),IF(COUNTBLANK(M9),L9,0),IF(COUNTBLANK(AA9),Y9,0)) -> 0 | AJ9: 조재부/이용암 | AK9: 12000 | AL9: =38064000+10250000 -> 48314000 | AP9: 950000 | AQ9: 14000000 | AR9: =SUM(AM9:AQ9) -> 14950000 | AW9: 48368500 | AX9: =표1_3[[#This Row],[총실행가]]-AL9-AR9-AW9 -> -6632500 | AY9: =AX9/표1_3[[#This Row],[총실행가]] -> -0.063166667 | AZ9: 20884000 | BA9: =표1_3[[#This Row],[총실행가]]-AL9-AR9-AZ9 -> 20852000 | BB9: =BA9/표1_3[[#This Row],[총실행가]] -> 0.19859048
A10: 6 | B10: 45980 | C10: 삼성리페어링 | D10: 신도림쌍용플래티넘노블 | E10: 12200000 | F10: 7500000 | K10: 0 | P10: 0 | U10: 0 | W10: 7500000 | X10: 1050000 | Y10: 6450000 | Z10: 45993 | AA10: 46006 | AB10: 46022 | AE10: =IF(COUNT(AC10),0,Y10) -> 6450000 | AG10: =(K10+P10+표1_3[[#This Row],[미수금액2]])-AH10 -> 6450000 | AH10: 0 | AJ10: 박성훈/장진호 | AL10: 4700000 | AM10: 1000000 | AP10: 50000 | AR10: 1050000 | AW10: 3262164 | AX10: =표1_3[[#This Row],[총실행가]]-AL10-AR10-AW10 -> 3187836 | AY10: =AX10/표1_3[[#This Row],[총실행가]] -> 0.26129803 | AZ10: 1552476 | BA10: =표1_3[[#This Row],[총실행가]]-AL10-AR10-AZ10 -> 4897524 | BB10: =BA10/표1_3[[#This Row],[총실행가]] -> 0.40143639
A11: 7 | B11: 45797 | C11: 적산건설 | D11: 원주기업도시2차 호반베르디움 | E11: 184400000 | F11: =표1_3[[#This Row],[총실행가]]-AL11 -> 118854000 | G11: =F11*20% -> 23770800 | H11: 45797 | I11: 45838 | K11: =IF(COUNT(J11),0,G11) -> 23770800 | L11: =F11*40% -> 47541600 | M11: 45817 | N11: 45838 | P11: =IF(COUNT(O11),0,L11) -> 47541600 | U11: =IF(COUNT(T11),0,Q11) -> 0 | W11: =F11*40% -> 47541600 | X11: =AR11 -> 550000 | Y11: =W11-X11 -> 46991600 | Z11: 45815 | AA11: 45832 | AB11: 45853 | AE11: =IF(COUNT(AC11),0,Y11) -> 46991600 | AG11: =(K11+P11+표1_3[[#This Row],[미수금액2]])-AH11 -> 118304000 | AH11: =SUM(IF(COUNTBLANK(H11),G11,0),IF(COUNTBLANK(M11),L11,0),IF(COUNTBLANK(AA11),Y11,0)) -> 0 | AJ11: 김병석 | AK11: 13000 | AL11: 65546000 | AP11: 550000 | AR11: 550000 | AW11: 81545500 | AX11: =표1_3[[#This Row],[총실행가]]-AL11-AR11-AW11 -> 36758500 | AY11: =AX11/표1_3[[#This Row],[총실행가]] -> 0.19934111 | AZ11: 40525900 | BA11: =표1_3[[#This Row],[총실행가]]-AL11-AR11-AZ11 -> 77778100 | BB11: =BA11/표1_3[[#This Row],[총실행가]] -> 0.42179013
A12: 8 | B12: 45853 | C12: 한국전문건설 | D12: 오창롯데캐슬더하이스트 | E12: 389400000 | F12: =E12-AL12 -> 233706000 | G12: =F12*10% -> 23370600 | H12: 45855 | I12: 45877 | J12: 45877 | K12: =IF(COUNT(J12),0,G12) -> 0 | L12: =F12*40% -> 93482400 | M12: 45915 | N12: 45976 | P12: =IF(COUNT(O12),0,L12) -> 93482400 | U12: =IF(COUNT(T12),0,Q12) -> 0 | V12: =표1_3[[#This Row],[금액]] -> 23370600 | W12: =F12*50% -> 116853000 | X12: =AR12 -> 2400000 | Y12: =W12-X12 -> 114453000 | Z12: 45964 | AA12: 45972 | AB12: 45989 | AE12: =IF(COUNT(AC12),0,Y12) -> 114453000 | AG12: =(K12+P12+표1_3[[#This Row],[미수금액2]])-AH12 -> 207935400 | AH12: =SUM(IF(COUNTBLANK(H12),G12,0),IF(COUNTBLANK(M12),L12,0),IF(COUNTBLANK(AA12),Y12,0)) -> 0 | AJ12: 조재부/조병철 | AK12: 14000 | AL12: 155694000 | AP12: 2400000 | AR12: 2400000 | AW12: 188438100 | AX12: =표1_3[[#This Row],[총실행가]]-AL12-AR12-AW12 -> 42867900 | AY12: =AX12/표1_3[[#This Row],[총실행가]] -> 0.11008706 | AZ12: 95783900 | BA12: =표1_3[[#This Row],[총실행가]]-AL12-AR12-AZ12 -> 135522100 | BB12: =BA12/표1_3[[#This Row],[총실행가]] -> 0.34802799
AE13: =IF(COUNT(AC13),0,Y13) -> 0 | AG13: =(K13+P13+표1_3[[#This Row],[미수금액2]])-AH13 -> 0
A14: 1 | B14: 45912 | C14: 석민이앤씨 | D14: 아시아선수촌 | E14: 430000000 | F14: =E14-AL14 -> 261710000 | G14: =F14*20% -> 52342000 | H14: 45932 | I14: 45961 | J14: 45945 | K14: =IF(COUNT(J14),0,G14) -> 0 | L14: =F14*40% -> 104684000 | M14: 45975 | N14: 46006 | O14: 46006 | P14: =IF(COUNT(O14),0,L14) -> 0 | U14: =IF(COUNT(T14),0,Q14) -> 0 | V14: =표1_3[[#This Row],[금액]]+표1_3[[#This Row],[금액2]] -> 157026000 | W14: =F14*40% -> 104684000 | X14: =AR14 -> 0 | Y14: =W14-X14 -> 104684000 | Z14: 46010 | AE14: =IF(COUNT(AC14),0,Y14) -> 104684000 | AG14: =(K14+P14+표1_3[[#This Row],[미수금액2]])-AH14 -> 0 | AH14: =SUM(IF(COUNTBLANK(H14),G14,0),IF(COUNTBLANK(M14),L14,0),IF(COUNTBLANK(AA14),Y14,0)) -> 104684000 | AJ14: 이준경/장진호 | AK14: 12000 | AL14: 168290000 | AR14: 0 | AX14: =표1_3[[#This Row],[총실행가]]-AL14-AR14-AW14 -> 261710000 | AY14: =AX14/표1_3[[#This Row],[총실행가]] -> 0.60862791 | BA14: =표1_3[[#This Row],[총실행가]]-AL14-AR14-AZ14 -> 261710000 | BB14: =BA14/표1_3[[#This Row],[총실행가]] -> 0.60862791
A15: 2 | B15: 45923 | C15: 명하시앤씨 | D15: 은빛마을6단지프라웰 | E15: 285000000 | F15: =E15-AL15 -> 181353000 | K15: =IF(COUNT(J15),0,G15) -> 0 | L15: =F15*60% -> 108811800 | M15: 45954 | N15: 45976 | O15: 45978 | P15: =IF(COUNT(O15),0,L15) -> 0 | U15: =IF(COUNT(T15),0,Q15) -> 0 | V15: =표1_3[[#This Row],[금액2]] -> 108811800 | W15: =F15*40% -> 72541200 | X15: =AR15 -> 0 | Y15: =W15-X15 -> 72541200 | AE15: =IF(COUNT(AC15),0,Y15) -> 72541200 | AG15: =(K15+P15+표1_3[[#This Row],[미수금액2]])-AH15 -> 0 | AH15: =SUM(IF(COUNTBLANK(H15),G15,0),IF(COUNTBLANK(M15),L15,0),IF(COUNTBLANK(AA15),Y15,0)) -> 72541200 | AJ15: 김용재 | AK15: 12,000/15,000 | AL15: 103647000 | AR15: 0 | AX15: =표1_3[[#This Row],[총실행가]]-AL15-AR15-AW15 -> 181353000 | AY15: =AX15/표1_3[[#This Row],[총실행가]] -> 0.63632632 | BA15: =표1_3[[#This Row],[총실행가]]-AL15-AR15-AZ15 -> 181353000 | BB15: =BA15/표1_3[[#This Row],[총실행가]] -> 0.63632632
A16: 3 | B16: 45950 | C16: 부영씨엔씨 | D16: 탑마을 타워빌 | E16: 425790000 | F16: =E16-AL16 -> 303876000 | G16: 91762800 | H16: 45947 | I16: 45976 | K16: =IF(COUNT(J16),0,G16) -> 91762800 | L16: 91762800 | M16: 45965 | N16: 45989 | P16: =IF(COUNT(O16),0,L16) -> 91762800 | U16: =IF(COUNT(T16),0,Q16) -> 0 | W16: =표1_3[[#This Row],[컨설팅 금액]]-표1_3[[#This Row],[금액]]-표1_3[[#This Row],[금액2]] -> 120350400 | X16: =AR16 -> 1300000 | Y16: =W16-X16 -> 119050400 | AE16: =IF(COUNT(AC16),0,Y16) -> 119050400 | AG16: =(K16+P16+표1_3[[#This Row],[미수금액2]])-AH16 -> 183525600 | AH16: =SUM(IF(COUNTBLANK(H16),G16,0),IF(COUNTBLANK(M16),L16,0),IF(COUNTBLANK(AA16),Y16,0)) -> 119050400 | AJ16: 이성수 신현섭/윤성환 | AK16: 13000 | AL16: 121914000 | AO16: 1300000 | AR16: 1300000 | AX16: =표1_3[[#This Row],[총실행가]]-AL16-AR16-AW16 -> 302576000 | AY16: =AX16/표1_3[[#This Row],[총실행가]] -> 0.71062261 | BA16: =표1_3[[#This Row],[총실행가]]-AL16-AR16-AZ16 -> 302576000 | BB16: =BA16/표1_3[[#This Row],[총실행가]] -> 0.71062261
A17: 4 | B17: 45957 | C17: 이음건설 | D17: 행원마을 동아솔레시티 | E17: 450000000 | F17: =E17-AL17 -> 272578000 | G17: =F17*20% -> 54515600 | H17: 45964 | I17: 45976 | J17: 45970 | K17: =IF(COUNT(J17),0,G17) -> 0 | L17: =F17*40% -> 109031200 | P17: =IF(COUNT(O17),0,L17) -> 109031200 | U17: =IF(COUNT(T17),0,Q17) -> 0 | V17: =표1_3[[#This Row],[금액]] -> 54515600 | W17: =F17*40% -> 109031200 | X17: =AR17 -> 0 | Y17: =W17-X17 -> 109031200 | AE17: =IF(COUNT(AC17),0,Y17) -> 109031200 | AG17: =(K17+P17+표1_3[[#This Row],[미수금액2]])-AH17 -> 0 | AH17: =SUM(IF(COUNTBLANK(H17),G17,0),IF(COUNTBLANK(M17),L17,0),IF(COUNTBLANK(AA17),Y17,0)) -> 218062400 | AJ17: 조종억 | AK17: 19000 | AL17: 177422000 | AR17: 0 | AX17: =표1_3[[#This Row],[총실행가]]-AL17-AR17-AW17 -> 272578000 | AY17: =AX17/표1_3[[#This Row],[총실행가]] -> 0.60572889 | BA17: =표1_3[[#This Row],[총실행가]]-AL17-AR17-AZ17 -> 272578000 | BB17: =BA17/표1_3[[#This Row],[총실행가]] -> 0.60572889
A18: 5 | B18: 45943 | C18: 에이치제이건설 | D18: 해운대 센텀트루엘 | F18: 133800000 | G18: =F18*20% -> 26760000 | H18: 45967 | I18: 45989 | K18: =IF(COUNT(J18),0,G18) -> 26760000 | L18: =F18*40% -> 53520000 | M18: 46010 | N18: 46022 | P18: =IF(COUNT(O18),0,L18) -> 53520000 | U18: =IF(COUNT(T18),0,Q18) -> 0 | W18: =F18*40% -> 53520000 | X18: =AR18 -> 0 | Y18: =W18-X18 -> 53520000 | AE18: =IF(COUNT(AC18),0,Y18) -> 53520000 | AG18: =(K18+P18+표1_3[[#This Row],[미수금액2]])-AH18 -> 80280000 | AH18: =SUM(IF(COUNTBLANK(H18),G18,0),IF(COUNTBLANK(M18),L18,0),IF(COUNTBLANK(AA18),Y18,0)) -> 53520000 | AX18: =표1_3[[#This Row],[총실행가]]-AL18-AR18-AW18 -> 0 | AY18: =AX18/표1_3[[#This Row],[총실행가]] -> #DIV/0! | BA18: =표1_3[[#This Row],[총실행가]]-AL18-AR18-AZ18 -> 0 | BB18: =BA18/표1_3[[#This Row],[총실행가]] -> #DIV/0!
A19: 6 | B19: 45979 | C19: 석민이앤씨 | D19: 강서힐스테이트 | E19: 114700000 | F19: =E19-AL19 -> 59588500 | G19: =F19*20% -> 11917700 | H19: 45979 | I19: 45989 | J19: 45989 | K19: =IF(COUNT(J19),0,G19) -> 0 | L19: =F19*40% -> 23835400 | P19: =IF(COUNT(O19),0,L19) -> 23835400 | U19: =IF(COUNT(T19),0,Q19) -> 0 | V19: =표1_3[[#This Row],[금액]] -> 11917700 | W19: =F19*40% -> 23835400 | X19: =AR19 -> 0 | Y19: =W19-X19 -> 23835400 | AE19: =IF(COUNT(AC19),0,Y19) -> 23835400 | AG19: =(K19+P19+표1_3[[#This Row],[미수금액2]])-AH19 -> 0 | AH19: =SUM(IF(COUNTBLANK(H19),G19,0),IF(COUNTBLANK(M19),L19,0),IF(COUNTBLANK(AA19),Y19,0)) -> 47670800 | AJ19: 이성수 | AK19: 18500 | AL19: 55111500 | AR19: 0 | AX19: =표1_3[[#This Row],[총실행가]]-AL19-AR19-AW19 -> 59588500 | AY19: =AX19/표1_3[[#This Row],[총실행가]] -> 0.51951613 | BA19: =표1_3[[#This Row],[총실행가]]-AL19-AR19-AZ19 -> 59588500 | BB19: =BA19/표1_3[[#This Row],[총실행가]] -> 0.51951613
A20: 7 | B20: 45987 | C20: 여름건설 | D20: 원불교안암교당 | E20: 46890000 | F20: =E20-AL20 -> 36890000 | G20: =F20*40% -> 14756000 | H20: 45988 | I20: 46006 | J20: 45989 | K20: =IF(COUNT(J20),0,G20) -> 0 | L20: =F20*40% -> 14756000 | P20: =IF(COUNT(O20),0,L20) -> 14756000 | U20: =IF(COUNT(T20),0,Q20) -> 0 | V20: =표1_3[[#This Row],[금액]] -> 14756000 | W20: =F20*20% -> 7378000 | X20: =AR20 -> 0 | Y20: =W20-X20 -> 7378000 | AE20: =IF(COUNT(AC20),0,Y20) -> 7378000 | AG20: =(K20+P20+표1_3[[#This Row],[미수금액2]])-AH20 -> 0 | AH20: =SUM(IF(COUNTBLANK(H20),G20,0),IF(COUNTBLANK(M20),L20,0),IF(COUNTBLANK(AA20),Y20,0)) -> 22134000 | AJ20: 조병철/손영구 | AK20: 14000 | AL20: 10000000 | AR20: 0 | AX20: =표1_3[[#This Row],[총실행가]]-AL20-AR20-AW20 -> 36890000 | AY20: =AX20/표1_3[[#This Row],[총실행가]] -> 0.78673491 | BA20: =표1_3[[#This Row],[총실행가]]-AL20-AR20-AZ20 -> 36890000 | BB20: =BA20/표1_3[[#This Row],[총실행가]] -> 0.78673491
A21: 8 | B21: 46000 | C21: 신화건설 | D21: 광명노온정수장 | E21: 14500000 | F21: =E21-AL21 -> 10336000 | K21: =IF(COUNT(J21),0,G21) -> 0 | P21: =IF(COUNT(O21),0,L21) -> 0 | U21: =IF(COUNT(T21),0,Q21) -> 0 | W21: =F21 -> 10336000 | X21: =AR21 -> 0 | Y21: =W21-X21 -> 10336000 | Z21: 46003 | AE21: =IF(COUNT(AC21),0,Y21) -> 10336000 | AG21: =(K21+P21+표1_3[[#This Row],[미수금액2]])-AH21 -> 0 | AH21: =SUM(IF(COUNTBLANK(H21),G21,0),IF(COUNTBLANK(M21),L21,0),IF(COUNTBLANK(AA21),Y21,0)) -> 10336000 | AJ21: 정상혁 | AK21: 12000 | AL21: 4164000 | AR21: 0 | AX21: =표1_3[[#This Row],[총실행가]]-AL21-AR21-AW21 -> 10336000 | AY21: =AX21/표1_3[[#This Row],[총실행가]] -> 0.71282759 | BA21: =표1_3[[#This Row],[총실행가]]-AL21-AR21-AZ21 -> 10336000 | BB21: =BA21/표1_3[[#This Row],[총실행가]] -> 0.71282759
A24: 2. 특허료 매출 | F24: 특허 자문료 (1%)-A | K24: 특허 자문료 (0.5%)-B | P24: 수금관련 | R24: 비고
A25: 순 번 | B25: 특허 자문료 공문 발송 일자 | C25: 업체명 | D25: 현장명 | E25: 낙찰 금액 | F25: 금액 | G25: 발행 | H25: 예정 | I25: 입금 | J25: 미수금액 | K25: 금액2 | L25: 발행3 | M25: 예정4 | N25: 입금5 | O25: 미수금액6 | P25: 수금액 | Q25: 미수금액2
A26: 1 | B26: 45597 | C26: 신화건설 | D26: 금곡하나 | E26: 136000000 | F26: =E26*1% -> 1360000 | G26: 45597 | H26: 45688 | I26: 45664 | J26: =IF(COUNT(I26),0,F26) -> 0 | O26: =IF(COUNT(N26),0,K26) -> 0 | P26: =F26 -> 1360000
A27: =A26+1 -> 2 | B27: 45665 | C27: 초담건설 | D27: 마곡수명산파크2단지 | E27: 226400000 | J27: =IF(COUNT(I27),0,F27) -> 0 | K27: =E27*0.5% -> 1132000 | L27: 45665 | M27: 45665 | N27: 45665 | O27: =IF(COUNT(N27),0,K27) -> 0 | P27: =K27 -> 1132000
A28: =A27+1 -> 3 | B28: 45665 | C28: 이루미건설 | D28: 한강신도시반도유보라2차 | E28: 215200000 | J28: =IF(COUNT(I28),0,F28) -> 0 | K28: =E28*0.5% -> 1076000 | L28: 45665 | M28: 45666 | N28: 45666 | O28: =IF(COUNT(N28),0,K28) -> 0 | P28: =K28 -> 1076000
A29: =A28+1 -> 4 | B29: 45667 | C29: 대표건설 | D29: 영종도힐스테이트 | E29: 87800000 | F29: =(E29*1%)-295000 -> 583000 | G29: 45670 | I29: 45671 | J29: =IF(COUNT(I29),0,F29) -> 0 | O29: =IF(COUNT(N29),0,K29) -> 0 | P29: =표6[[#This Row],[금액]] -> 583000 | R29: 자재 구매-590,000원(295,000원 차감)
A30: =A29+1 -> 5 | B30: 45670 | C30: 진성이앤지 | D30: 길동현대 | E30: 214800000 | J30: =IF(COUNT(I30),0,F30) -> 0 | K30: =E30*0.5% -> 1074000 | L30: 45670 | M30: 45672 | N30: 45672 | O30: =IF(COUNT(N30),0,K30) -> 0 | P30: =표6[[#This Row],[금액2]] -> 1074000
A31: =A30+1 -> 6 | B31: 45667 | C31: 진성이앤지 | D31: 일산 센트럴아이파크 | E31: 40000000 | F31: =(E31*1%) -> 400000 | G31: 45671 | I31: 45672 | J31: =IF(COUNT(I31),0,F31) -> 0 | O31: =IF(COUNT(N31),0,K31) -> 0 | P31: =F31 -> 400000
A32: =A31+1 -> 7 | B32: 45668 | C32: 진성이앤지 | D32: 문촌 뉴삼익 | E32: 429800000 | F32: =(E32*1%)-3461000 -> 837000 | G32: 45671 | I32: 45672 | J32: =IF(COUNT(I32),0,F32) -> 0 | O32: =IF(COUNT(N32),0,K32) -> 0 | P32: =F32 -> 837000 | R32: 자재 구매-3,461,000원(837,000원 차감)
A33: =A32+1 -> 8 | B33: 45669 | C33: 진성이앤지 | D33: 백마마을3단지금호한양 | E33: 26000000 | F33: =(E33*1%)-116500 -> 143500 | G33: 45671 | I33: 45672 | J33: =IF(COUNT(I33),0,F33) -> 0 | O33: =IF(COUNT(N33),0,K33) -> 0 | P33: =F33 -> 143500 | R33: 자재 구매-233,000원(116,500원 차감)
A34: =A33+1 -> 9 | B34: 45671 | C34: 예은건설 | D34: 인천논현힐스테이트 | E34: 425000000 | F34: =(E34*1%)-2550000 -> 1700000 | G34: 45671 | H34: 45698 | I34: 45698 | J34: =IF(COUNT(I34),0,F34) -> 0 | O34: =IF(COUNT(N34),0,K34) -> 0 | P34: =표6[[#This Row],[금액]] -> 1700000 | R34: 자재 구매-5,100,000(2,550,000원 차감)
A35: =A34+1 -> 10 | B35: 45604 | C35: 엘케이개발 | D35: 현대성우5차 | E35: 199800000 | J35: =IF(COUNT(I35),0,F35) -> 0 | K35: =(E35*0.5%) -> 999000 | L35: 45671 | M35: 45716 | N35: 45693 | O35: =IF(COUNT(N35),0,K35) -> 0 | P35: =표6[[#This Row],[금액2]] -> 999000
A36: =A35+1 -> 11 | B36: 45671 | C36: 코지건설 | D36: 아름마을 태영 | E36: 329500000 | F36: =(E36*1%) -> 3295000 | G36: 45671 | H36: 45716 | I36: 45681 | J36: =IF(COUNT(I36),0,F36) -> 0 | O36: =IF(COUNT(N36),0,K36) -> 0 | P36: =표6[[#This Row],[금액]] -> 3295000
A37: =A36+1 -> 12 | B37: 45671 | C37: 코지건설 | D37: 안서대림2차 | E37: 98800000 | F37: =(E37*1%)-193150 -> 794850 | G37: 45671 | H37: 45716 | I37: 45681 | J37: =IF(COUNT(I37),0,F37) -> 0 | O37: =IF(COUNT(N37),0,K37) -> 0 | P37: =표6[[#This Row],[금액]] -> 794850 | R37: 자재 구매-386,300(193,150원 차감)
A38: =A37+1 -> 13 | B38: 45667 | C38: 대한진단건설 | D38: 신구덕우성 | E38: 21100000 | F38: =(E38*1%) -> 211000 | G38: 45671 | H38: 45681 | I38: 45681 | J38: =IF(COUNT(I38),0,F38) -> 0 | O38: =IF(COUNT(N38),0,K38) -> 0 | P38: =표6[[#This Row],[금액]] -> 211000 | Q38: 0
A39: =A38+1 -> 14 | B39: 45671 | C39: 이루미건설 | D39: 이매촌청구 | E39: 84900000 | F39: =(E39*1%)-675000 -> 174000 | G39: 45672 | I39: 45672 | J39: =IF(COUNT(I39),0,F39) -> 0 | O39: =IF(COUNT(N39),0,K39) -> 0 | P39: =표6[[#This Row],[금액]] -> 174000 | R39: 자재 구매-1,350,000 (675,000원 차감)
A40: =A39+1 -> 15 | B40: 45672 | C40: 엘케이개발 | D40: 홍성 청솔 | E40: 194900000 | J40: =IF(COUNT(I40),0,F40) -> 0 | K40: =표6[[#This Row],[낙찰 금액]]*0.5% -> 974500 | L40: 45674 | M40: 45747 | N40: 45693 | O40: =IF(COUNT(N40),0,K40) -> 0 | P40: =표6[[#This Row],[금액2]] -> 974500 | Q40: =IF(COUNT(O40),0,L40) -> 0
A41: =A40+1 -> 16 | B41: 45672 | C41: 엘케이개발 | D41: 2차 그린맨션 | E41: 618000000 | J41: =IF(COUNT(I41),0,F41) -> 0 | K41: =E41*0.5% -> 3090000 | L41: 45674 | M41: 45747 | N41: 45693 | O41: =IF(COUNT(N41),0,K41) -> 0 | P41: =표6[[#This Row],[금액2]] -> 3090000 | Q41: =IF(COUNT(O41),0,L41) -> 0
A42: =A41+1 -> 17 | B42: 45681 | C42: 지앤필드종합건설 | D42: 옥빛마을14단지 부영 | E42: 472000000 | F42: =(E42*1%)-224000 -> 4496000 | G42: 45681 | H42: 45747 | I42: 45694 | J42: =IF(COUNT(I42),0,F42) -> 0 | O42: =IF(COUNT(N42),0,K42) -> 0 | P42: =표6[[#This Row],[금액]] -> 4496000 | Q42: =IF(COUNT(O42),0,L42) -> 0 | R42: 자재 구매-448,000 (224,000원 차감)
